Workbook
Name TRE_TASK: 'Công thức & Hệ số'!$B$77
Name CATALOG_POINTS: 'Công thức & Hệ số'!$C$24:$C$50
Name HS_SEM: 'Công thức & Hệ số'!$B$59
Name OTHER_POINTS: 'Công thức & Hệ số'!$C$51
Name TRE_NGAY: 'Công thức & Hệ số'!$B$78
Name W_BONUS: 'Công thức & Hệ số'!$B$13
Name W_DOKHO: 'Công thức & Hệ số'!$B$11
Name W_SL: 'Công thức & Hệ số'!$B$10
Name HS_PROX5: 'Công thức & Hệ số'!$B$56
Name TASK_TARGET: 'Công thức & Hệ số'!$B$19
Name HS_MAX: 'Công thức & Hệ số'!$B$64
Name HS_MIN: 'Công thức & Hệ số'!$B$63
Name DAILY_POST_POINTS: 'Công thức & Hệ số'!$B$90
Name HS_PROX4: 'Công thức & Hệ số'!$B$57
Name W_CL: 'Công thức & Hệ số'!$B$12
Name HS_SE1: 'Công thức & Hệ số'!$B$60
Name HS_PROX3: 'Công thức & Hệ số'!$B$58
Name CATALOG_BASE: 'Công thức & Hệ số'!$D$24:$D$50
Name CATALOG_TASK: 'Công thức & Hệ số'!$B$24:$B$50
Name HS_DEFAULT: 'Công thức & Hệ số'!$B$62
Name PCT_WARN: 'Công thức & Hệ số'!$B$15
Name HS_E0: 'Công thức & Hệ số'!$B$61

Sheet Công thức & Hệ số
A1: CÔNG THỨC TÍNH KPI DESIGNER — MAC MEDIA (2 bước, thang điểm 100%)
A2: Cập nhật: 01/07/2026 · Nguồn điểm/loại task: bảng kpi_catalog trên Supabase (bolt-native-database-67011175)
A4: Công thức tổng (2 bước):
A5: Bước 1 — Trọng số tổng số task: Tổng điểm thô = Σ (số lượng mỗi loại task × điểm/task loại đó, tra ở mục 3)
A6: Bước 2 — Quy đổi % và cộng các điểm khác: TỔNG ĐIỂM KPI (%) = Điểm số lượng + Điểm độ khó + Điểm chất lượng + Điểm bonus/trễ hạn
A7: Điểm số lượng = MIN(Tổng điểm thô ÷ Chỉ tiêu, 1) × trọng số Số lượng (mục 1). Task có tên KHÔNG khớp danh mục ở mục 3 sẽ tự tính theo điểm của "[Design] Other (Khác)".
A9: 1. TRỌNG SỐ THANG ĐIỂM 100%
A10: Điểm số lượng — tối đa (%) | B10: 60
A11: Điểm độ khó — tối đa (%) | B11: 15
A12: Điểm chất lượng — tối đa (%) | B12: 15
A13: Điểm bonus — tối đa (%) | B13: 10
A14: Tổng kiểm tra (nên = 100) | B14: =$B$10+$B$11+$B$12+$B$13 -> 100
A15: Ngưỡng "Gần đạt" (%) | B15: 85
A16: 4 trọng số nên cộng lại = 100.
A18: 2. CHỈ TIÊU ĐIỂM SỐ LƯỢNG (bước 1)
A19: Chỉ tiêu điểm số lượng (điểm/tháng) | B19: 150
A20: VD: 150 điểm/tháng — tương đương ~75 task loại "Other" (2đ/task), hoặc ít hơn nếu làm nhiều task điểm cao (Video, R&D...).
A22: 3. DANH MỤC ĐIỂM THEO LOẠI TASK (nguồn: kpi_catalog trên Supabase)
A23: Nhóm | B23: Loại task | C23: Điểm/task | D23: Tên gốc (dò khi không khớp tuyệt đối)
A24: Branding | B24: [Design] Ava - Cover | C24: 1 | D24: =IFERROR(LEFT(B24,FIND(" (",B24)-1),B24) -> [Design] Ava - Cover
A25: Branding | B25: [Design] Logo | C25: 2 | D25: =IFERROR(LEFT(B25,FIND(" (",B25)-1),B25) -> [Design] Logo
A26: Company Tasks | B26: R&D | C26: 8 | D26: =IFERROR(LEFT(B26,FIND(" (",B26)-1),B26) -> R&D
A27: Company Tasks | B27: Task Inhouse | C27: 2 | D27: =IFERROR(LEFT(B27,FIND(" (",B27)-1),B27) -> Task Inhouse
A28: Company Tasks | B28: Video Inhouse | C28: 6 | D28: =IFERROR(LEFT(B28,FIND(" (",B28)-1),B28) -> Video Inhouse
A29: Fix & Other | B29: [Design] Fix - Design (Sửa lỗi thiết kế) | C29: 1 | D29: =IFERROR(LEFT(B29,FIND(" (",B29)-1),B29) -> [Design] Fix - Design
A30: Fix & Other | B30: [Design] Fix - Video (Sửa lỗi video) | C30: 6 | D30: =IFERROR(LEFT(B30,FIND(" (",B30)-1),B30) -> [Design] Fix - Video
A31: Fix & Other | B31: [Design] Other (Khác) | C31: 2 | D31: =IFERROR(LEFT(B31,FIND(" (",B31)-1),B31) -> [Design] Other
A32: Gift & Promo | B32: [Design] Gift Card | C32: 2 | D32: =IFERROR(LEFT(B32,FIND(" (",B32)-1),B32) -> [Design] Gift Card
A33: Gift & Promo | B33: [Design] Gift Card - Gift Voucher/Coupon | C33: 2 | D33: =IFERROR(LEFT(B33,FIND(" (",B33)-1),B33) -> [Design] Gift Card - Gift Voucher/Coupon
A34: Gift & Promo | B34: [Design] Gift Card - Holder | C34: 2 | D34: =IFERROR(LEFT(B34,FIND(" (",B34)-1),B34) -> [Design] Gift Card - Holder
A35: Gift & Promo | B35: [Design] Promotion | C35: 2 | D35: =IFERROR(LEFT(B35,FIND(" (",B35)-1),B35) -> [Design] Promotion
... A50: Video | B50: [Design] Video - Monthly | C50: 8 | D50: =IFERROR(LEFT(B50,FIND(" (",B50)-1),B50) -> [Design] Video - Monthly
A51: Điểm mặc định khi task KHÔNG khớp danh mục (= "Other (Khác)") | C51: {=INDEX($C$24:$C$50,MATCH("[Design] Other (Khác)",$B$24:$B$50,0))} -> 2
A52: Cập nhật điểm ở đây khi công ty đổi cách tính KPI trên app — toàn bộ bảng tính sẽ tự cập nhật theo. Khớp tên task theo 2 bước: (1) khớp tuyệt đối cột Loại task, (2) nếu không khớp, dò xem tên task có BẮT ĐẦU bằng "Tên gốc" của dòng nào không (bỏ qua phần mô tả trong ngoặc) — không khớp cả hai thì tính theo "Other (Khác)".
A54: 4. HỆ SỐ ĐỘ KHÓ THEO GÓI DỊCH VỤ (trục riêng — độ phức tạp gói client, không phải loại task)
A55: Gói dịch vụ | B55: Hệ số điểm/task
A56: PROX5 | B56: 1.5
A57: PROX4 | B57: 1.3
A58: PROX3 | B58: 1.1
A59: SEM | B59: 1
...

Sheet Bảng điểm T6
A1: BẢNG TÍNH ĐIỂM KPI DESIGNER — THÁNG 6/2026 (chỉ dùng file check mới nhất, không lọc status) | AB1: 🏆 BẢNG XẾP HẠNG (tự động, giảm dần theo Tổng điểm KPI)
A2: Designer | B2: Nhóm | C2: Tổng số task | D2: Tổng điểm thô (loại task) | E2: PROX5 | F2: PROX4 | G2: PROX3 | H2: SEM | I2: SE1 | J2: E0 | K2: Đã phân loại gói | L2: Hệ số độ khó TB | M2: Điểm số lượng | N2: Điểm độ khó | O2: Chất lượng TB (1-5) | P2: Điểm chất lượng | Q2: Số task trễ hạn | R2: Tổng ngày trễ | S2: Điểm bonus | T2: Ghi chú bonus | U2: Điểm bonus/trễ | V2: TỔNG ĐIỂM KPI (%) | W2: Xếp hạng | X2: Trạng thái | Z2: Khoá (ẩn) | AB2: Hạng | AC2: Designer | AD2: Nhóm | AE2: Tổng điểm (%) | AF2: Trạng thái
A3: Helia | B3: Media Key | C3: =COUNTIF('Data thô T6'!$B:$B,A3) -> 250 | D3: =SUMIF('Data thô T6'!$B:$B,A3,'Data thô T6'!$C:$C) -> 362 | E3: =COUNTIFS('Data thô T6'!$B:$B,A3,'Data thô T6'!$E:$E,"PROX5") -> 4 | F3: =COUNTIFS('Data thô T6'!$B:$B,A3,'Data thô T6'!$E:$E,"PROX4") -> 63 | G3: =COUNTIFS('Data thô T6'!$B:$B,A3,'Data thô T6'!$E:$E,"PROX3") -> 166 | H3: =COUNTIFS('Data thô T6'!$B:$B,A3,'Data thô T6'!$E:$E,"SEM") -> 0 | I3: =COUNTIFS('Data thô T6'!$B:$B,A3,'Data thô T6'!$E:$E,"SE1") -> 0 | J3: =COUNTIFS('Data thô T6'!$B:$B,A3,'Data thô T6'!$E:$E,"E0") -> 6 | K3: =SUM(E3:J3) -> 239 | L3: =IF(C3=0,0,(E3*HS_PROX5+F3*HS_PROX4+G3*HS_PROX3+H3*HS_SEM+I3*HS_SE1+J3*HS_E0+(C3-K3)*HS_DEFAULT)/C3) -> 1.1428 | M3: =MIN(D3/TASK_TARGET,1)*W_SL -> 60 | N3: =IF(C3=0,0,MAX(0,MIN(1,(L3-HS_MIN)/(HS_MAX-HS_MIN)))*W_DOKHO) -> 8.3025 | P3: =IF(O3="","",(O3/5)*W_CL) | Q3: 0 | R3: 0 | S3: 0 | U3: =MIN(S3,W_BONUS)+Q3*TRE_TASK+R3*TRE_NGAY -> 0 | V3: =M3+N3+IF(P3="",0,P3)+U3 -> 68.3025 | W3: =RANK(V3,$V$3:$V$27,0) -> 5 | X3: =IF(V3>=(W_SL+W_DOKHO+W_CL+W_BONUS),"✅ Đạt KPI",IF(V3>=PCT_WARN,"⚠️ Gần đạt KPI","❌ Chưa đạt")) -> ❌ Chưa đạt | Z3: =V3+(ROW()-3)/100000000 -> 68.3025 | AB3: 1 | AC3: {=INDEX($A$3:$A$27,MATCH(LARGE($Z$3:$Z$27,1),$Z$3:$Z$27,0))} -> Sherry | AD3: {=INDEX($B$3:$B$27,MATCH(LARGE($Z$3:$Z$27,1),$Z$3:$Z$27,0))} -> Media Key | AE3: {=INDEX($V$3:$V$27,MATCH(LARGE($Z$3:$Z$27,1),$Z$3:$Z$27,0))} -> 69.737903 | AF3: =IF(AE3>=(W_SL+W_DOKHO+W_CL+W_BONUS),"✅ Đạt KPI",IF(AE3>=PCT_WARN,"⚠️ Gần đạt KPI","❌ Chưa đạt")) -> ❌ Chưa đạt
A4: Clara | B4: Media Key | C4: =COUNTIF('Data thô T6'!$B:$B,A4) -> 250 | D4: =SUMIF('Data thô T6'!$B:$B,A4,'Data thô T6'!$C:$C) -> 355 | E4: =COUNTIFS('Data thô T6'!$B:$B,A4,'Data thô T6'!$E:$E,"PROX5") -> 14 | F4: =COUNTIFS('Data thô T6'!$B:$B,A4,'Data thô T6'!$E:$E,"PROX4") -> 44 | G4: =COUNTIFS('Data thô T6'!$B:$B,A4,'Data thô T6'!$E:$E,"PROX3") -> 161 | H4: =COUNTIFS('Data thô T6'!$B:$B,A4,'Data thô T6'!$E:$E,"SEM") -> 0 | I4: =COUNTIFS('Data thô T6'!$B:$B,A4,'Data thô T6'!$E:$E,"SE1") -> 0 | J4: =COUNTIFS('Data thô T6'!$B:$B,A4,'Data thô T6'!$E:$E,"E0") -> 11 | K4: =SUM(E4:J4) -> 230 | L4: =IF(C4=0,0,(E4*HS_PROX5+F4*HS_PROX4+G4*HS_PROX3+H4*HS_SEM+I4*HS_SE1+J4*HS_E0+(C4-K4)*HS_DEFAULT)/C4) -> 1.132 | M4: =MIN(D4/TASK_TARGET,1)*W_SL -> 60 | N4: =IF(C4=0,0,MAX(0,MIN(1,(L4-HS_MIN)/(HS_MAX-HS_MIN)))*W_DOKHO) -> 8.1 | P4: =IF(O4="","",(O4/5)*W_CL) | Q4: 0 | R4: 0 | S4: 0 | U4: =MIN(S4,W_BONUS)+Q4*TRE_TASK+R4*TRE_NGAY -> 0 | V4: =M4+N4+IF(P4="",0,P4)+U4 -> 68.1 | W4: =RANK(V4,$V$3:$V$27,0) -> 7 | X4: =IF(V4>=(W_SL+W_DOKHO+W_CL+W_BONUS),"✅ Đạt KPI",IF(V4>=PCT_WARN,"⚠️ Gần đạt KPI","❌ Chưa đạt")) -> ❌ Chưa đạt | Z4: =V4+(ROW()-3)/100000000 -> 68.1 | AB4: 2 | AC4: {=INDEX($A$3:$A$27,MATCH(LARGE($Z$3:$Z$27,2),$Z$3:$Z$27,0))} -> Nancy | AD4: {=INDEX($B$3:$B$27,MATCH(LARGE($Z$3:$Z$27,2),$Z$3:$Z$27,0))} -> Media Key | AE4: {=INDEX($V$3:$V$27,MATCH(LARGE($Z$3:$Z$27,2),$Z$3:$Z$27,0))} -> 69.236111 | AF4: =IF(AE4>=(W_SL+W_DOKHO+W_CL+W_BONUS),"✅ Đạt KPI",IF(AE4>=PCT_WARN,"⚠️ Gần đạt KPI","❌ Chưa đạt")) -> ❌ Chưa đạt
A5: Daniel | B5: Media Key | C5: =COUNTIF('Data thô T6'!$B:$B,A5) -> 246 | D5: =SUMIF('Data thô T6'!$B:$B,A5,'Data thô T6'!$C:$C) -> 379 | E5: =COUNTIFS('Data thô T6'!$B:$B,A5,'Data thô T6'!$E:$E,"PROX5") -> 2 | F5: =COUNTIFS('Data thô T6'!$B:$B,A5,'Data thô T6'!$E:$E,"PROX4") -> 47 | G5: =COUNTIFS('Data thô T6'!$B:$B,A5,'Data thô T6'!$E:$E,"PROX3") -> 149 | H5: =COUNTIFS('Data thô T6'!$B:$B,A5,'Data thô T6'!$E:$E,"SEM") -> 1 | I5: =COUNTIFS('Data thô T6'!$B:$B,A5,'Data thô T6'!$E:$E,"SE1") -> 0 | J5: =COUNTIFS('Data thô T6'!$B:$B,A5,'Data thô T6'!$E:$E,"E0") -> 19 | K5: =SUM(E5:J5) -> 218 | L5: =IF(C5=0,0,(E5*HS_PROX5+F5*HS_PROX4+G5*HS_PROX3+H5*HS_SEM+I5*HS_SE1+J5*HS_E0+(C5-K5)*HS_DEFAULT)/C5) -> 1.0987805 | M5: =MIN(D5/TASK_TARGET,1)*W_SL -> 60 | N5: =IF(C5=0,0,MAX(0,MIN(1,(L5-HS_MIN)/(HS_MAX-HS_MIN)))*W_DOKHO) -> 7.4771341 | P5: =IF(O5="","",(O5/5)*W_CL) | Q5: 0 | R5: 0 | S5: 0 | U5: =MIN(S5,W_BONUS)+Q5*TRE_TASK+R5*TRE_NGAY -> 0 | V5: =M5+N5+IF(P5="",0,P5)+U5 -> 67.477134 | W5: =RANK(V5,$V$3:$V$27,0) -> 13 | X5: =IF(V5>=(W_SL+W_DOKHO+W_CL+W_BONUS),"✅ Đạt KPI",IF(V5>=PCT_WARN,"⚠️ Gần đạt KPI","❌ Chưa đạt")) -> ❌ Chưa đạt | Z5: =V5+(ROW()-3)/100000000 -> 67.477134 | AB5: 3 | AC5: {=INDEX($A$3:$A$27,MATCH(LARGE($Z$3:$Z$27,3),$Z$3:$Z$27,0))} -> Mio | AD5: {=INDEX($B$3:$B$27,MATCH(LARGE($Z$3:$Z$27,3),$Z$3:$Z$27,0))} -> Media Key | AE5: {=INDEX($V$3:$V$27,MATCH(LARGE($Z$3:$Z$27,3),$Z$3:$Z$27,0))} -> 68.457237 | AF5: =IF(AE5>=(W_SL+W_DOKHO+W_CL+W_BONUS),"✅ Đạt KPI",IF(AE5>=PCT_WARN,"⚠️ Gần đạt KPI","❌ Chưa đạt")) -> ❌ Chưa đạt
A6: Heidi | B6: Media Key | C6: =COUNTIF('Data thô T6'!$B:$B,A6) -> 220 | D6: =SUMIF('Data thô T6'!$B:$B,A6,'Data thô T6'!$C:$C) -> 330 | E6: =COUNTIFS('Data thô T6'!$B:$B,A6,'Data thô T6'!$E:$E,"PROX5") -> 0 | F6: =COUNTIFS('Data thô T6'!$B:$B,A6,'Data thô T6'!$E:$E,"PROX4") -> 34 | G6: =COUNTIFS('Data thô T6'!$B:$B,A6,'Data thô T6'!$E:$E,"PROX3") -> 156 | H6: =COUNTIFS('Data thô T6'!$B:$B,A6,'Data thô T6'!$E:$E,"SEM") -> 0 | I6: =COUNTIFS('Data thô T6'!$B:$B,A6,'Data thô T6'!$E:$E,"SE1") -> 0 | J6: =COUNTIFS('Data thô T6'!$B:$B,A6,'Data thô T6'!$E:$E,"E0") -> 10 | K6: =SUM(E6:J6) -> 200 | L6: =IF(C6=0,0,(E6*HS_PROX5+F6*HS_PROX4+G6*HS_PROX3+H6*HS_SEM+I6*HS_SE1+J6*HS_E0+(C6-K6)*HS_DEFAULT)/C6) -> 1.1036364 | M6: =MIN(D6/TASK_TARGET,1)*W_SL -> 60 | N6: =IF(C6=0,0,MAX(0,MIN(1,(L6-HS_MIN)/(HS_MAX-HS_MIN)))*W_DOKHO) -> 7.5681818 | P6: =IF(O6="","",(O6/5)*W_CL) | Q6: 0 | R6: 0 | S6: 0 | U6: =MIN(S6,W_BONUS)+Q6*TRE_TASK+R6*TRE_NGAY -> 0 | V6: =M6+N6+IF(P6="",0,P6)+U6 -> 67.568182 | W6: =RANK(V6,$V$3:$V$27,0) -> 12 | X6: =IF(V6>=(W_SL+W_DOKHO+W_CL+W_BONUS),"✅ Đạt KPI",IF(V6>=PCT_WARN,"⚠️ Gần đạt KPI","❌ Chưa đạt")) -> ❌ Chưa đạt | Z6: =V6+(ROW()-3)/100000000 -> 67.568182 | AB6: 4 | AC6: {=INDEX($A$3:$A$27,MATCH(LARGE($Z$3:$Z$27,4),$Z$3:$Z$27,0))} -> Charlie | AD6: {=INDEX($B$3:$B$27,MATCH(LARGE($Z$3:$Z$27,4),$Z$3:$Z$27,0))} -> Media Key | AE6: {=INDEX($V$3:$V$27,MATCH(LARGE($Z$3:$Z$27,4),$Z$3:$Z$27,0))} -> 68.4375 | AF6: =IF(AE6>=(W_SL+W_DOKHO+W_CL+W_BONUS),"✅ Đạt KPI",IF(AE6>=PCT_WARN,"⚠️ Gần đạt KPI","❌ Chưa đạt")) -> ❌ Chưa đạt
A7: Barry | B7: Media Key | C7: =COUNTIF('Data thô T6'!$B:$B,A7) -> 217 | D7: =SUMIF('Data thô T6'!$B:$B,A7,'Data thô T6'!$C:$C) -> 328 | E7: =COUNTIFS('Data thô T6'!$B:$B,A7,'Data thô T6'!$E:$E,"PROX5") -> 11 | F7: =COUNTIFS('Data thô T6'!$B:$B,A7,'Data thô T6'!$E:$E,"PROX4") -> 49 | G7: =COUNTIFS('Data thô T6'!$B:$B,A7,'Data thô T6'!$E:$E,"PROX3") -> 110 | H7: =COUNTIFS('Data thô T6'!$B:$B,A7,'Data thô T6'!$E:$E,"SEM") -> 4 | I7: =COUNTIFS('Data thô T6'!$B:$B,A7,'Data thô T6'!$E:$E,"SE1") -> 5 | J7: =COUNTIFS('Data thô T6'!$B:$B,A7,'Data thô T6'!$E:$E,"E0") -> 20 | K7: =SUM(E7:J7) -> 199 | L7: =IF(C7=0,0,(E7*HS_PROX5+F7*HS_PROX4+G7*HS_PROX3+H7*HS_SEM+I7*HS_SE1+J7*HS_E0+(C7-K7)*HS_DEFAULT)/C7) -> 1.1138249 | M7: =MIN(D7/TASK_TARGET,1)*W_SL -> 60 | N7: =IF(C7=0,0,MAX(0,MIN(1,(L7-HS_MIN)/(HS_MAX-HS_MIN)))*W_DOKHO) -> 7.7592166 | P7: =IF(O7="","",(O7/5)*W_CL) | Q7: 0 | R7: 0 | S7: 0 | U7: =MIN(S7,W_BONUS)+Q7*TRE_TASK+R7*TRE_NGAY -> 0 | V7: =M7+N7+IF(P7="",0,P7)+U7 -> 67.759217 | W7: =RANK(V7,$V$3:$V$27,0) -> 9 | X7: =IF(V7>=(W_SL+W_DOKHO+W_CL+W_BONUS),"✅ Đạt KPI",IF(V7>=PCT_WARN,"⚠️ Gần đạt KPI","❌ Chưa đạt")) -> ❌ Chưa đạt | Z7: =V7+(ROW()-3)/100000000 -> 67.759217 | AB7: 5 | AC7: {=INDEX($A$3:$A$27,MATCH(LARGE($Z$3:$Z$27,5),$Z$3:$Z$27,0))} -> Helia | AD7: {=INDEX($B$3:$B$27,MATCH(LARGE($Z$3:$Z$27,5),$Z$3:$Z$27,0))} -> Media Key | AE7: {=INDEX($V$3:$V$27,MATCH(LARGE($Z$3:$Z$27,5),$Z$3:$Z$27,0))} -> 68.3025 | AF7: =IF(AE7>=(W_SL+W_DOKHO+W_CL+W_BONUS),"✅ Đạt KPI",IF(AE7>=PCT_WARN,"⚠️ Gần đạt KPI","❌ Chưa đạt")) -> ❌ Chưa đạt
A8: Alex | B8: Media Key | C8: =COUNTIF('Data thô T6'!$B:$B,A8) -> 213 | D8: =SUMIF('Data thô T6'!$B:$B,A8,'Data thô T6'!$C:$C) -> 289 | E8: =COUNTIFS('Data thô T6'!$B:$B,A8,'Data thô T6'!$E:$E,"PROX5") -> 17 | F8: =COUNTIFS('Data thô T6'!$B:$B,A8,'Data thô T6'!$E:$E,"PROX4") -> 32 | G8: =COUNTIFS('Data thô T6'!$B:$B,A8,'Data thô T6'!$E:$E,"PROX3") -> 120 | H8: =COUNTIFS('Data thô T6'!$B:$B,A8,'Data thô T6'!$E:$E,"SEM") -> 0 | I8: =COUNTIFS('Data thô T6'!$B:$B,A8,'Data thô T6'!$E:$E,"SE1") -> 0 | J8: =COUNTIFS('Data thô T6'!$B:$B,A8,'Data thô T6'!$E:$E,"E0") -> 33 | K8: =SUM(E8:J8) -> 202 | L8: =IF(C8=0,0,(E8*HS_PROX5+F8*HS_PROX4+G8*HS_PROX3+H8*HS_SEM+I8*HS_SE1+J8*HS_E0+(C8-K8)*HS_DEFAULT)/C8) -> 1.0948357 | M8: =MIN(D8/TASK_TARGET,1)*W_SL -> 60 | N8: =IF(C8=0,0,MAX(0,MIN(1,(L8-HS_MIN)/(HS_MAX-HS_MIN)))*W_DOKHO) -> 7.403169 | P8: =IF(O8="","",(O8/5)*W_CL) | Q8: 0 | R8: 0 | S8: 0 | U8: =MIN(S8,W_BONUS)+Q8*TRE_TASK+R8*TRE_NGAY -> 0 | V8: =M8+N8+IF(P8="",0,P8)+U8 -> 67.403169 | W8: =RANK(V8,$V$3:$V$27,0) -> 14 | X8: =IF(V8>=(W_SL+W_DOKHO+W_CL+W_BONUS),"✅ Đạt KPI",IF(V8>=PCT_WARN,"⚠️ Gần đạt KPI","❌ Chưa đạt")) -> ❌ Chưa đạt | Z8: =V8+(ROW()-3)/100000000 -> 67.403169 | AB8: 6 | AC8: {=INDEX($A$3:$A$27,MATCH(LARGE($Z$3:$Z$27,6),$Z$3:$Z$27,0))} -> Titus | AD8: {=INDEX($B$3:$B$27,MATCH(LARGE($Z$3:$Z$27,6),$Z$3:$Z$27,0))} -> Media Key | AE8: {=INDEX($V$3:$V$27,MATCH(LARGE($Z$3:$Z$27,6),$Z$3:$Z$27,0))} -> 68.259375 | AF8: =IF(AE8>=(W_SL+W_DOKHO+W_CL+W_BONUS),"✅ Đạt KPI",IF(AE8>=PCT_WARN,"⚠️ Gần đạt KPI","❌ Chưa đạt")) -> ❌ Chưa đạt
A9: Ocean | B9: Media Key | C9: =COUNTIF('Data thô T6'!$B:$B,A9) -> 202 | D9: =SUMIF('Data thô T6'!$B:$B,A9,'Data thô T6'!$C:$C) -> 279 | E9: =COUNTIFS('Data thô T6'!$B:$B,A9,'Data thô T6'!$E:$E,"PROX5") -> 13 | F9: =COUNTIFS('Data thô T6'!$B:$B,A9,'Data thô T6'!$E:$E,"PROX4") -> 42 | G9: =COUNTIFS('Data thô T6'!$B:$B,A9,'Data thô T6'!$E:$E,"PROX3") -> 102 | H9: =COUNTIFS('Data thô T6'!$B:$B,A9,'Data thô T6'!$E:$E,"SEM") -> 0 | I9: =COUNTIFS('Data thô T6'!$B:$B,A9,'Data thô T6'!$E:$E,"SE1") -> 9 | J9: =COUNTIFS('Data thô T6'!$B:$B,A9,'Data thô T6'!$E:$E,"E0") -> 21 | K9: =SUM(E9:J9) -> 187 | L9: =IF(C9=0,0,(E9*HS_PROX5+F9*HS_PROX4+G9*HS_PROX3+H9*HS_SEM+I9*HS_SE1+J9*HS_E0+(C9-K9)*HS_DEFAULT)/C9) -> 1.1094059 | M9: =MIN(D9/TASK_TARGET,1)*W_SL -> 60 | N9: =IF(C9=0,0,MAX(0,MIN(1,(L9-HS_MIN)/(HS_MAX-HS_MIN)))*W_DOKHO) -> 7.6763614 | P9: =IF(O9="","",(O9/5)*W_CL) | Q9: 0 | R9: 0 | S9: 0 | U9: =MIN(S9,W_BONUS)+Q9*TRE_TASK+R9*TRE_NGAY -> 0 | V9: =M9+N9+IF(P9="",0,P9)+U9 -> 67.676361 | W9: =RANK(V9,$V$3:$V$27,0) -> 10 | X9: =IF(V9>=(W_SL+W_DOKHO+W_CL+W_BONUS),"✅ Đạt KPI",IF(V9>=PCT_WARN,"⚠️ Gần đạt KPI","❌ Chưa đạt")) -> ❌ Chưa đạt | Z9: =V9+(ROW()-3)/100000000 -> 67.676361 | AB9: 7 | AC9: {=INDEX($A$3:$A$27,MATCH(LARGE($Z$3:$Z$27,7),$Z$3:$Z$27,0))} -> Clara | AD9: {=INDEX($B$3:$B$27,MATCH(LARGE($Z$3:$Z$27,7),$Z$3:$Z$27,0))} -> Media Key | AE9: {=INDEX($V$3:$V$27,MATCH(LARGE($Z$3:$Z$27,7),$Z$3:$Z$27,0))} -> 68.1 | AF9: =IF(AE9>=(W_SL+W_DOKHO+W_CL+W_BONUS),"✅ Đạt KPI",IF(AE9>=PCT_WARN,"⚠️ Gần đạt KPI","❌ Chưa đạt")) -> ❌ Chưa đạt
A10: Titus | B10: Media Key | C10: =COUNTIF('Data thô T6'!$B:$B,A10) -> 200 | D10: =SUMIF('Data thô T6'!$B:$B,A10,'Data thô T6'!$C:$C) -> 270 | E10: =COUNTIFS('Data thô T6'!$B:$B,A10,'Data thô T6'!$E:$E,"PROX5") -> 8 | F10: =COUNTIFS('Data thô T6'!$B:$B,A10,'Data thô T6'!$E:$E,"PROX4") -> 39 | G10: =COUNTIFS('Data thô T6'!$B:$B,A10,'Data thô T6'!$E:$E,"PROX3") -> 139 | H10: =COUNTIFS('Data thô T6'!$B:$B,A10,'Data thô T6'!$E:$E,"SEM") -> 2 | I10: =COUNTIFS('Data thô T6'!$B:$B,A10,'Data thô T6'!$E:$E,"SE1") -> 0 | J10: =COUNTIFS('Data thô T6'!$B:$B,A10,'Data thô T6'!$E:$E,"E0") -> 5 | K10: =SUM(E10:J10) -> 193 | L10: =IF(C10=0,0,(E10*HS_PROX5+F10*HS_PROX4+G10*HS_PROX3+H10*HS_SEM+I10*HS_SE1+J10*HS_E0+(C10-K10)*HS_DEFAULT)/C10) -> 1.1405 | M10: =MIN(D10/TASK_TARGET,1)*W_SL -> 60 | N10: =IF(C10=0,0,MAX(0,MIN(1,(L10-HS_MIN)/(HS_MAX-HS_MIN)))*W_DOKHO) -> 8.259375 | P10: =IF(O10="","",(O10/5)*W_CL) | Q10: 0 | R10: 0 | S10: 0 | U10: =MIN(S10,W_BONUS)+Q10*TRE_TASK+R10*TRE_NGAY -> 0 | V10: =M10+N10+IF(P10="",0,P10)+U10 -> 68.259375 | W10: =RANK(V10,$V$3:$V$27,0) -> 6 | X10: =IF(V10>=(W_SL+W_DOKHO+W_CL+W_BONUS),"✅ Đạt KPI",IF(V10>=PCT_WARN,"⚠️ Gần đạt KPI","❌ Chưa đạt")) -> ❌ Chưa đạt | Z10: =V10+(ROW()-3)/100000000 -> 68.259375 | AB10: 8 | AC10: {=INDEX($A$3:$A$27,MATCH(LARGE($Z$3:$Z$27,8),$Z$3:$Z$27,0))} -> Julie | AD10: {=INDEX($B$3:$B$27,MATCH(LARGE($Z$3:$Z$27,8),$Z$3:$Z$27,0))} -> Media Key | AE10: {=INDEX($V$3:$V$27,MATCH(LARGE($Z$3:$Z$27,8),$Z$3:$Z$27,0))} -> 68.015351 | AF10: =IF(AE10>=(W_SL+W_DOKHO+W_CL+W_BONUS),"✅ Đạt KPI",IF(AE10>=PCT_WARN,"⚠️ Gần đạt KPI","❌ Chưa đạt")) -> ❌ Chưa đạt
A11: Leon Le | B11: Media Key | C11: =COUNTIF('Data thô T6'!$B:$B,A11) -> 194 | D11: =SUMIF('Data thô T6'!$B:$B,A11,'Data thô T6'!$C:$C) -> 266 | E11: =COUNTIFS('Data thô T6'!$B:$B,A11,'Data thô T6'!$E:$E,"PROX5") -> 7 | F11: =COUNTIFS('Data thô T6'!$B:$B,A11,'Data thô T6'!$E:$E,"PROX4") -> 24 | G11: =COUNTIFS('Data thô T6'!$B:$B,A11,'Data thô T6'!$E:$E,"PROX3") -> 137 | H11: =COUNTIFS('Data thô T6'!$B:$B,A11,'Data thô T6'!$E:$E,"SEM") -> 1 | I11: =COUNTIFS('Data thô T6'!$B:$B,A11,'Data thô T6'!$E:$E,"SE1") -> 2 | J11: =COUNTIFS('Data thô T6'!$B:$B,A11,'Data thô T6'!$E:$E,"E0") -> 13 | K11: =SUM(E11:J11) -> 184 | L11: =IF(C11=0,0,(E11*HS_PROX5+F11*HS_PROX4+G11*HS_PROX3+H11*HS_SEM+I11*HS_SE1+J11*HS_E0+(C11-K11)*HS_DEFAULT)/C11) -> 1.1046392 | M11: =MIN(D11/TASK_TARGET,1)*W_SL -> 60 | N11: =IF(C11=0,0,MAX(0,MIN(1,(L11-HS_MIN)/(HS_MAX-HS_MIN)))*W_DOKHO) -> 7.5869845 | P11: =IF(O11="","",(O11/5)*W_CL) | Q11: 0 | R11: 0 | S11: 0 | U11: =MIN(S11,W_BONUS)+Q11*TRE_TASK+R11*TRE_NGAY -> 0 | V11: =M11+N11+IF(P11="",0,P11)+U11 -> 67.586985 | W11: =RANK(V11,$V$3:$V$27,0) -> 11 | X11: =IF(V11>=(W_SL+W_DOKHO+W_CL+W_BONUS),"✅ Đạt KPI",IF(V11>=PCT_WARN,"⚠️ Gần đạt KPI","❌ Chưa đạt")) -> ❌ Chưa đạt | Z11: =V11+(ROW()-3)/100000000 -> 67.586985 | AB11: 9 | AC11: {=INDEX($A$3:$A$27,MATCH(LARGE($Z$3:$Z$27,9),$Z$3:$Z$27,0))} -> Barry | AD11: {=INDEX($B$3:$B$27,MATCH(LARGE($Z$3:$Z$27,9),$Z$3:$Z$27,0))} -> Media Key | AE11: {=INDEX($V$3:$V$27,MATCH(LARGE($Z$3:$Z$27,9),$Z$3:$Z$27,0))} -> 67.759217 | AF11: =IF(AE11>=(W_SL+W_DOKHO+W_CL+W_BONUS),"✅ Đạt KPI",IF(AE11>=PCT_WARN,"⚠️ Gần đạt KPI","❌ Chưa đạt")) -> ❌ Chưa đạt
A12: Mio | B12: Media Key | C12: =COUNTIF('Data thô T6'!$B:$B,A12) -> 190 | D12: =SUMIF('Data thô T6'!$B:$B,A12,'Data thô T6'!$C:$C) -> 249 | E12: =COUNTIFS('Data thô T6'!$B:$B,A12,'Data thô T6'!$E:$E,"PROX5") -> 8 | F12: =COUNTIFS('Data thô T6'!$B:$B,A12,'Data thô T6'!$E:$E,"PROX4") -> 48 | G12: =COUNTIFS('Data thô T6'!$B:$B,A12,'Data thô T6'!$E:$E,"PROX3") -> 124 | H12: =COUNTIFS('Data thô T6'!$B:$B,A12,'Data thô T6'!$E:$E,"SEM") -> 1 | I12: =COUNTIFS('Data thô T6'!$B:$B,A12,'Data thô T6'!$E:$E,"SE1") -> 0 | J12: =COUNTIFS('Data thô T6'!$B:$B,A12,'Data thô T6'!$E:$E,"E0") -> 7 | K12: =SUM(E12:J12) -> 188 | L12: =IF(C12=0,0,(E12*HS_PROX5+F12*HS_PROX4+G12*HS_PROX3+H12*HS_SEM+I12*HS_SE1+J12*HS_E0+(C12-K12)*HS_DEFAULT)/C12) -> 1.1510526 | M12: =MIN(D12/TASK_TARGET,1)*W_SL -> 60 | N12: =IF(C12=0,0,MAX(0,MIN(1,(L12-HS_MIN)/(HS_MAX-HS_MIN)))*W_DOKHO) -> 8.4572368 | P12: =IF(O12="","",(O12/5)*W_CL) | Q12: 0 | R12: 0 | S12: 0 | U12: =MIN(S12,W_BONUS)+Q12*TRE_TASK+R12*TRE_NGAY -> 0 | V12: =M12+N12+IF(P12="",0,P12)+U12 -> 68.457237 | W12: =RANK(V12,$V$3:$V$27,0) -> 3 | X12: =IF(V12>=(W_SL+W_DOKHO+W_CL+W_BONUS),"✅ Đạt KPI",IF(V12>=PCT_WARN,"⚠️ Gần đạt KPI","❌ Chưa đạt")) -> ❌ Chưa đạt | Z12: =V12+(ROW()-3)/100000000 -> 68.457237 | AB12: 10 | AC12: {=INDEX($A$3:$A$27,MATCH(LARGE($Z$3:$Z$27,10),$Z$3:$Z$27,0))} -> Ocean | AD12: {=INDEX($B$3:$B$27,MATCH(LARGE($Z$3:$Z$27,10),$Z$3:$Z$27,0))} -> Media Key | AE12: {=INDEX($V$3:$V$27,MATCH(LARGE($Z$3:$Z$27,10),$Z$3:$Z$27,0))} -> 67.676361 | AF12: =IF(AE12>=(W_SL+W_DOKHO+W_CL+W_BONUS),"✅ Đạt KPI",IF(AE12>=PCT_WARN,"⚠️ Gần đạt KPI","❌ Chưa đạt")) -> ❌ Chưa đạt
A13: Julie | B13: Media Key | C13: =COUNTIF('Data thô T6'!$B:$B,A13) -> 171 | D13: =SUMIF('Data thô T6'!$B:$B,A13,'Data thô T6'!$C:$C) -> 229 | E13: =COUNTIFS('Data thô T6'!$B:$B,A13,'Data thô T6'!$E:$E,"PROX5") -> 5 | F13: =COUNTIFS('Data thô T6'!$B:$B,A13,'Data thô T6'!$E:$E,"PROX4") -> 35 | G13: =COUNTIFS('Data thô T6'!$B:$B,A13,'Data thô T6'!$E:$E,"PROX3") -> 112 | H13: =COUNTIFS('Data thô T6'!$B:$B,A13,'Data thô T6'!$E:$E,"SEM") -> 1 | I13: =COUNTIFS('Data thô T6'!$B:$B,A13,'Data thô T6'!$E:$E,"SE1") -> 0 | J13: =COUNTIFS('Data thô T6'!$B:$B,A13,'Data thô T6'!$E:$E,"E0") -> 8 | K13: =SUM(E13:J13) -> 161 | L13: =IF(C13=0,0,(E13*HS_PROX5+F13*HS_PROX4+G13*HS_PROX3+H13*HS_SEM+I13*HS_SE1+J13*HS_E0+(C13-K13)*HS_DEFAULT)/C13) -> 1.1274854 | M13: =MIN(D13/TASK_TARGET,1)*W_SL -> 60 | N13: =IF(C13=0,0,MAX(0,MIN(1,(L13-HS_MIN)/(HS_MAX-HS_MIN)))*W_DOKHO) -> 8.0153509 | P13: =IF(O13="","",(O13/5)*W_CL) | Q13: 0 | R13: 0 | S13: 0 | U13: =MIN(S13,W_BONUS)+Q13*TRE_TASK+R13*TRE_NGAY -> 0 | V13: =M13+N13+IF(P13="",0,P13)+U13 -> 68.015351 | W13: =RANK(V13,$V$3:$V$27,0) -> 8 | X13: =IF(V13>=(W_SL+W_DOKHO+W_CL+W_BONUS),"✅ Đạt KPI",IF(V13>=PCT_WARN,"⚠️ Gần đạt KPI","❌ Chưa đạt")) -> ❌ Chưa đạt | Z13: =V13+(ROW()-3)/100000000 -> 68.015351 | AB13: 11 | AC13: {=INDEX($A$3:$A$27,MATCH(LARGE($Z$3:$Z$27,11),$Z$3:$Z$27,0))} -> Leon Le | AD13: {=INDEX($B$3:$B$27,MATCH(LARGE($Z$3:$Z$27,11),$Z$3:$Z$27,0))} -> Media Key | AE13: {=INDEX($V$3:$V$27,MATCH(LARGE($Z$3:$Z$27,11),$Z$3:$Z$27,0))} -> 67.586985 | AF13: =IF(AE13>=(W_SL+W_DOKHO+W_CL+W_BONUS),"✅ Đạt KPI",IF(AE13>=PCT_WARN,"⚠️ Gần đạt KPI","❌ Chưa đạt")) -> ❌ Chưa đạt
A14: My | B14: Media CTV | C14: =COUNTIF('Data thô T6'!$B:$B,A14) -> 81 | D14: =SUMIF('Data thô T6'!$B:$B,A14,'Data thô T6'!$C:$C) -> 81 | E14: =COUNTIFS('Data thô T6'!$B:$B,A14,'Data thô T6'!$E:$E,"PROX5") -> 1 | F14: =COUNTIFS('Data thô T6'!$B:$B,A14,'Data thô T6'!$E:$E,"PROX4") -> 15 | G14: =COUNTIFS('Data thô T6'!$B:$B,A14,'Data thô T6'!$E:$E,"PROX3") -> 41 | H14: =COUNTIFS('Data thô T6'!$B:$B,A14,'Data thô T6'!$E:$E,"SEM") -> 1 | I14: =COUNTIFS('Data thô T6'!$B:$B,A14,'Data thô T6'!$E:$E,"SE1") -> 1 | J14: =COUNTIFS('Data thô T6'!$B:$B,A14,'Data thô T6'!$E:$E,"E0") -> 11 | K14: =SUM(E14:J14) -> 70 | L14: =IF(C14=0,0,(E14*HS_PROX5+F14*HS_PROX4+G14*HS_PROX3+H14*HS_SEM+I14*HS_SE1+J14*HS_E0+(C14-K14)*HS_DEFAULT)/C14) -> 1.0703704 | M14: =MIN(D14/TASK_TARGET,1)*W_SL -> 32.4 | N14: =IF(C14=0,0,MAX(0,MIN(1,(L14-HS_MIN)/(HS_MAX-HS_MIN)))*W_DOKHO) -> 6.9444444 | P14: =IF(O14="","",(O14/5)*W_CL) | Q14: 0 | R14: 0 | S14: 0 | U14: =MIN(S14,W_BONUS)+Q14*TRE_TASK+R14*TRE_NGAY -> 0 | V14: =M14+N14+IF(P14="",0,P14)+U14 -> 39.344444 | W14: =RANK(V14,$V$3:$V$27,0) -> 20 | X14: =IF(V14>=(W_SL+W_DOKHO+W_CL+W_BONUS),"✅ Đạt KPI",IF(V14>=PCT_WARN,"⚠️ Gần đạt KPI","❌ Chưa đạt")) -> ❌ Chưa đạt | Z14: =V14+(ROW()-3)/100000000 -> 39.344445 | AB14: 12 | AC14: {=INDEX($A$3:$A$27,MATCH(LARGE($Z$3:$Z$27,12),$Z$3:$Z$27,0))} -> Heidi | AD14: {=INDEX($B$3:$B$27,MATCH(LARGE($Z$3:$Z$27,12),$Z$3:$Z$27,0))} -> Media Key | AE14: {=INDEX($V$3:$V$27,MATCH(LARGE($Z$3:$Z$27,12),$Z$3:$Z$27,0))} -> 67.568182 | AF14: =IF(AE14>=(W_SL+W_DOKHO+W_CL+W_BONUS),"✅ Đạt KPI",IF(AE14>=PCT_WARN,"⚠️ Gần đạt KPI","❌ Chưa đạt")) -> ❌ Chưa đạt
A15: Vi | B15: Media CTV | C15: =COUNTIF('Data thô T6'!$B:$B,A15) -> 80 | D15: =SUMIF('Data thô T6'!$B:$B,A15,'Data thô T6'!$C:$C) -> 80 | E15: =COUNTIFS('Data thô T6'!$B:$B,A15,'Data thô T6'!$E:$E,"PROX5") -> 1 | F15: =COUNTIFS('Data thô T6'!$B:$B,A15,'Data thô T6'!$E:$E,"PROX4") -> 10 | G15: =COUNTIFS('Data thô T6'!$B:$B,A15,'Data thô T6'!$E:$E,"PROX3") -> 55 | H15: =COUNTIFS('Data thô T6'!$B:$B,A15,'Data thô T6'!$E:$E,"SEM") -> 0 | I15: =COUNTIFS('Data thô T6'!$B:$B,A15,'Data thô T6'!$E:$E,"SE1") -> 1 | J15: =COUNTIFS('Data thô T6'!$B:$B,A15,'Data thô T6'!$E:$E,"E0") -> 5 | K15: =SUM(E15:J15) -> 72 | L15: =IF(C15=0,0,(E15*HS_PROX5+F15*HS_PROX4+G15*HS_PROX3+H15*HS_SEM+I15*HS_SE1+J15*HS_E0+(C15-K15)*HS_DEFAULT)/C15) -> 1.0925 | M15: =MIN(D15/TASK_TARGET,1)*W_SL -> 32 | N15: =IF(C15=0,0,MAX(0,MIN(1,(L15-HS_MIN)/(HS_MAX-HS_MIN)))*W_DOKHO) -> 7.359375 | P15: =IF(O15="","",(O15/5)*W_CL) | Q15: 0 | R15: 0 | S15: 0 | U15: =MIN(S15,W_BONUS)+Q15*TRE_TASK+R15*TRE_NGAY -> 0 | V15: =M15+N15+IF(P15="",0,P15)+U15 -> 39.359375 | W15: =RANK(V15,$V$3:$V$27,0) -> 19 | X15: =IF(V15>=(W_SL+W_DOKHO+W_CL+W_BONUS),"✅ Đạt KPI",IF(V15>=PCT_WARN,"⚠️ Gần đạt KPI","❌ Chưa đạt")) -> ❌ Chưa đạt | Z15: =V15+(ROW()-3)/100000000 -> 39.359375 | AB15: 13 | AC15: {=INDEX($A$3:$A$27,MATCH(LARGE($Z$3:$Z$27,13),$Z$3:$Z$27,0))} -> Daniel | AD15: {=INDEX($B$3:$B$27,MATCH(LARGE($Z$3:$Z$27,13),$Z$3:$Z$27,0))} -> Media Key | AE15: {=INDEX($V$3:$V$27,MATCH(LARGE($Z$3:$Z$27,13),$Z$3:$Z$27,0))} -> 67.477134 | AF15: =IF(AE15>=(W_SL+W_DOKHO+W_CL+W_BONUS),"✅ Đạt KPI",IF(AE15>=PCT_WARN,"⚠️ Gần đạt KPI","❌ Chưa đạt")) -> ❌ Chưa đạt
A16: Nah | B16: Media CTV | C16: =COUNTIF('Data thô T6'!$B:$B,A16) -> 80 | D16: =SUMIF('Data thô T6'!$B:$B,A16,'Data thô T6'!$C:$C) -> 80 | E16: =COUNTIFS('Data thô T6'!$B:$B,A16,'Data thô T6'!$E:$E,"PROX5") -> 1 | F16: =COUNTIFS('Data thô T6'!$B:$B,A16,'Data thô T6'!$E:$E,"PROX4") -> 16 | G16: =COUNTIFS('Data thô T6'!$B:$B,A16,'Data thô T6'!$E:$E,"PROX3") -> 37 | H16: =COUNTIFS('Data thô T6'!$B:$B,A16,'Data thô T6'!$E:$E,"SEM") -> 4 | I16: =COUNTIFS('Data thô T6'!$B:$B,A16,'Data thô T6'!$E:$E,"SE1") -> 3 | J16: =COUNTIFS('Data thô T6'!$B:$B,A16,'Data thô T6'!$E:$E,"E0") -> 12 | K16: =SUM(E16:J16) -> 73 | L16: =IF(C16=0,0,(E16*HS_PROX5+F16*HS_PROX4+G16*HS_PROX3+H16*HS_SEM+I16*HS_SE1+J16*HS_E0+(C16-K16)*HS_DEFAULT)/C16) -> 1.06375 | M16: =MIN(D16/TASK_TARGET,1)*W_SL -> 32 | N16: =IF(C16=0,0,MAX(0,MIN(1,(L16-HS_MIN)/(HS_MAX-HS_MIN)))*W_DOKHO) -> 6.8203125 | P16: =IF(O16="","",(O16/5)*W_CL) | Q16: 0 | R16: 0 | S16: 0 | U16: =MIN(S16,W_BONUS)+Q16*TRE_TASK+R16*TRE_NGAY -> 0 | V16: =M16+N16+IF(P16="",0,P16)+U16 -> 38.820312 | W16: =RANK(V16,$V$3:$V$27,0) -> 23 | X16: =IF(V16>=(W_SL+W_DOKHO+W_CL+W_BONUS),"✅ Đạt KPI",IF(V16>=PCT_WARN,"⚠️ Gần đạt KPI","❌ Chưa đạt")) -> ❌ Chưa đạt | Z16: =V16+(ROW()-3)/100000000 -> 38.820313 | AB16: 14 | AC16: {=INDEX($A$3:$A$27,MATCH(LARGE($Z$3:$Z$27,14),$Z$3:$Z$27,0))} -> Alex | AD16: {=INDEX($B$3:$B$27,MATCH(LARGE($Z$3:$Z$27,14),$Z$3:$Z$27,0))} -> Media Key | AE16: {=INDEX($V$3:$V$27,MATCH(LARGE($Z$3:$Z$27,14),$Z$3:$Z$27,0))} -> 67.403169 | AF16: =IF(AE16>=(W_SL+W_DOKHO+W_CL+W_BONUS),"✅ Đạt KPI",IF(AE16>=PCT_WARN,"⚠️ Gần đạt KPI","❌ Chưa đạt")) -> ❌ Chưa đạt
A17: Uri | B17: Media CTV | C17: =COUNTIF('Data thô T6'!$B:$B,A17) -> 80 | D17: =SUMIF('Data thô T6'!$B:$B,A17,'Data thô T6'!$C:$C) -> 80 | E17: =COUNTIFS('Data thô T6'!$B:$B,A17,'Data thô T6'!$E:$E,"PROX5") -> 6 | F17: =COUNTIFS('Data thô T6'!$B:$B,A17,'Data thô T6'!$E:$E,"PROX4") -> 12 | G17: =COUNTIFS('Data thô T6'!$B:$B,A17,'Data thô T6'!$E:$E,"PROX3") -> 42 | H17: =COUNTIFS('Data thô T6'!$B:$B,A17,'Data thô T6'!$E:$E,"SEM") -> 1 | I17: =COUNTIFS('Data thô T6'!$B:$B,A17,'Data thô T6'!$E:$E,"SE1") -> 1 | J17: =COUNTIFS('Data thô T6'!$B:$B,A17,'Data thô T6'!$E:$E,"E0") -> 8 | K17: =SUM(E17:J17) -> 70 | L17: =IF(C17=0,0,(E17*HS_PROX5+F17*HS_PROX4+G17*HS_PROX3+H17*HS_SEM+I17*HS_SE1+J17*HS_E0+(C17-K17)*HS_DEFAULT)/C17) -> 1.10375 | M17: =MIN(D17/TASK_TARGET,1)*W_SL -> 32 | N17: =IF(C17=0,0,MAX(0,MIN(1,(L17-HS_MIN)/(HS_MAX-HS_MIN)))*W_DOKHO) -> 7.5703125 | P17: =IF(O17="","",(O17/5)*W_CL) | Q17: 0 | R17: 0 | S17: 0 | U17: =MIN(S17,W_BONUS)+Q17*TRE_TASK+R17*TRE_NGAY -> 0 | V17: =M17+N17+IF(P17="",0,P17)+U17 -> 39.570312 | W17: =RANK(V17,$V$3:$V$27,0) -> 16 | X17: =IF(V17>=(W_SL+W_DOKHO+W_CL+W_BONUS),"✅ Đạt KPI",IF(V17>=PCT_WARN,"⚠️ Gần đạt KPI","❌ Chưa đạt")) -> ❌ Chưa đạt | Z17: =V17+(ROW()-3)/100000000 -> 39.570313 | AB17: 15 | AC17: {=INDEX($A$3:$A$27,MATCH(LARGE($Z$3:$Z$27,15),$Z$3:$Z$27,0))} -> Nathan | AD17: {=INDEX($B$3:$B$27,MATCH(LARGE($Z$3:$Z$27,15),$Z$3:$Z$27,0))} -> Media Key | AE17: {=INDEX($V$3:$V$27,MATCH(LARGE($Z$3:$Z$27,15),$Z$3:$Z$27,0))} -> 44.410294 | AF17: =IF(AE17>=(W_SL+W_DOKHO+W_CL+W_BONUS),"✅ Đạt KPI",IF(AE17>=PCT_WARN,"⚠️ Gần đạt KPI","❌ Chưa đạt")) -> ❌ Chưa đạt
A18: Q.Anh | B18: Media CTV | C18: =COUNTIF('Data thô T6'!$B:$B,A18) -> 80 | D18: =SUMIF('Data thô T6'!$B:$B,A18,'Data thô T6'!$C:$C) -> 80 | E18: =COUNTIFS('Data thô T6'!$B:$B,A18,'Data thô T6'!$E:$E,"PROX5") -> 0 | F18: =COUNTIFS('Data thô T6'!$B:$B,A18,'Data thô T6'!$E:$E,"PROX4") -> 12 | G18: =COUNTIFS('Data thô T6'!$B:$B,A18,'Data thô T6'!$E:$E,"PROX3") -> 50 | H18: =COUNTIFS('Data thô T6'!$B:$B,A18,'Data thô T6'!$E:$E,"SEM") -> 0 | I18: =COUNTIFS('Data thô T6'!$B:$B,A18,'Data thô T6'!$E:$E,"SE1") -> 3 | J18: =COUNTIFS('Data thô T6'!$B:$B,A18,'Data thô T6'!$E:$E,"E0") -> 7 | K18: =SUM(E18:J18) -> 72 | L18: =IF(C18=0,0,(E18*HS_PROX5+F18*HS_PROX4+G18*HS_PROX3+H18*HS_SEM+I18*HS_SE1+J18*HS_E0+(C18-K18)*HS_DEFAULT)/C18) -> 1.0775 | M18: =MIN(D18/TASK_TARGET,1)*W_SL -> 32 | N18: =IF(C18=0,0,MAX(0,MIN(1,(L18-HS_MIN)/(HS_MAX-HS_MIN)))*W_DOKHO) -> 7.078125 | P18: =IF(O18="","",(O18/5)*W_CL) | Q18: 0 | R18: 0 | S18: 0 | U18: =MIN(S18,W_BONUS)+Q18*TRE_TASK+R18*TRE_NGAY -> 0 | V18: =M18+N18+IF(P18="",0,P18)+U18 -> 39.078125 | W18: =RANK(V18,$V$3:$V$27,0) -> 22 | X18: =IF(V18>=(W_SL+W_DOKHO+W_CL+W_BONUS),"✅ Đạt KPI",IF(V18>=PCT_WARN,"⚠️ Gần đạt KPI","❌ Chưa đạt")) -> ❌ Chưa đạt | Z18: =V18+(ROW()-3)/100000000 -> 39.078125 | AB18: 16 | AC18: {=INDEX($A$3:$A$27,MATCH(LARGE($Z$3:$Z$27,16),$Z$3:$Z$27,0))} -> Uri | AD18: {=INDEX($B$3:$B$27,MATCH(LARGE($Z$3:$Z$27,16),$Z$3:$Z$27,0))} -> Media CTV | AE18: {=INDEX($V$3:$V$27,MATCH(LARGE($Z$3:$Z$27,16),$Z$3:$Z$27,0))} -> 39.570312 | AF18: =IF(AE18>=(W_SL+W_DOKHO+W_CL+W_BONUS),"✅ Đạt KPI",IF(AE18>=PCT_WARN,"⚠️ Gần đạt KPI","❌ Chưa đạt")) -> ❌ Chưa đạt
A19: Phat | B19: Media CTV | C19: =COUNTIF('Data thô T6'!$B:$B,A19) -> 80 | D19: =SUMIF('Data thô T6'!$B:$B,A19,'Data thô T6'!$C:$C) -> 80 | E19: =COUNTIFS('Data thô T6'!$B:$B,A19,'Data thô T6'!$E:$E,"PROX5") -> 0 | F19: =COUNTIFS('Data thô T6'!$B:$B,A19,'Data thô T6'!$E:$E,"PROX4") -> 13 | G19: =COUNTIFS('Data thô T6'!$B:$B,A19,'Data thô T6'!$E:$E,"PROX3") -> 48 | H19: =COUNTIFS('Data thô T6'!$B:$B,A19,'Data thô T6'!$E:$E,"SEM") -> 0 | I19: =COUNTIFS('Data thô T6'!$B:$B,A19,'Data thô T6'!$E:$E,"SE1") -> 0 | J19: =COUNTIFS('Data thô T6'!$B:$B,A19,'Data thô T6'!$E:$E,"E0") -> 3 | K19: =SUM(E19:J19) -> 64 | L19: =IF(C19=0,0,(E19*HS_PROX5+F19*HS_PROX4+G19*HS_PROX3+H19*HS_SEM+I19*HS_SE1+J19*HS_E0+(C19-K19)*HS_DEFAULT)/C19) -> 1.0975 | M19: =MIN(D19/TASK_TARGET,1)*W_SL -> 32 | N19: =IF(C19=0,0,MAX(0,MIN(1,(L19-HS_MIN)/(HS_MAX-HS_MIN)))*W_DOKHO) -> 7.453125 | P19: =IF(O19="","",(O19/5)*W_CL) | Q19: 0 | R19: 0 | S19: 0 | U19: =MIN(S19,W_BONUS)+Q19*TRE_TASK+R19*TRE_NGAY -> 0 | V19: =M19+N19+IF(P19="",0,P19)+U19 -> 39.453125 | W19: =RANK(V19,$V$3:$V$27,0) -> 18 | X19: =IF(V19>=(W_SL+W_DOKHO+W_CL+W_BONUS),"✅ Đạt KPI",IF(V19>=PCT_WARN,"⚠️ Gần đạt KPI","❌ Chưa đạt")) -> ❌ Chưa đạt | Z19: =V19+(ROW()-3)/100000000 -> 39.453125 | AB19: 17 | AC19: {=INDEX($A$3:$A$27,MATCH(LARGE($Z$3:$Z$27,17),$Z$3:$Z$27,0))} -> Meran | AD19: {=INDEX($B$3:$B$27,MATCH(LARGE($Z$3:$Z$27,17),$Z$3:$Z$27,0))} -> Media CTV | AE19: {=INDEX($V$3:$V$27,MATCH(LARGE($Z$3:$Z$27,17),$Z$3:$Z$27,0))} -> 39.546875 | AF19: =IF(AE19>=(W_SL+W_DOKHO+W_CL+W_BONUS),"✅ Đạt KPI",IF(AE19>=PCT_WARN,"⚠️ Gần đạt KPI","❌ Chưa đạt")) -> ❌ Chưa đạt
A20: Henri | B20: Media CTV | C20: =COUNTIF('Data thô T6'!$B:$B,A20) -> 80 | D20: =SUMIF('Data thô T6'!$B:$B,A20,'Data thô T6'!$C:$C) -> 80 | E20: =COUNTIFS('Data thô T6'!$B:$B,A20,'Data thô T6'!$E:$E,"PROX5") -> 1 | F20: =COUNTIFS('Data thô T6'!$B:$B,A20,'Data thô T6'!$E:$E,"PROX4") -> 10 | G20: =COUNTIFS('Data thô T6'!$B:$B,A20,'Data thô T6'!$E:$E,"PROX3") -> 48 | H20: =COUNTIFS('Data thô T6'!$B:$B,A20,'Data thô T6'!$E:$E,"SEM") -> 1 | I20: =COUNTIFS('Data thô T6'!$B:$B,A20,'Data thô T6'!$E:$E,"SE1") -> 1 | J20: =COUNTIFS('Data thô T6'!$B:$B,A20,'Data thô T6'!$E:$E,"E0") -> 5 | K20: =SUM(E20:J20) -> 66 | L20: =IF(C20=0,0,(E20*HS_PROX5+F20*HS_PROX4+G20*HS_PROX3+H20*HS_SEM+I20*HS_SE1+J20*HS_E0+(C20-K20)*HS_DEFAULT)/C20) -> 1.08375 | M20: =MIN(D20/TASK_TARGET,1)*W_SL -> 32 | N20: =IF(C20=0,0,MAX(0,MIN(1,(L20-HS_MIN)/(HS_MAX-HS_MIN)))*W_DOKHO) -> 7.1953125 | P20: =IF(O20="","",(O20/5)*W_CL) | Q20: 0 | R20: 0 | S20: 0 | U20: =MIN(S20,W_BONUS)+Q20*TRE_TASK+R20*TRE_NGAY -> 0 | V20: =M20+N20+IF(P20="",0,P20)+U20 -> 39.195312 | W20: =RANK(V20,$V$3:$V$27,0) -> 21 | X20: =IF(V20>=(W_SL+W_DOKHO+W_CL+W_BONUS),"✅ Đạt KPI",IF(V20>=PCT_WARN,"⚠️ Gần đạt KPI","❌ Chưa đạt")) -> ❌ Chưa đạt | Z20: =V20+(ROW()-3)/100000000 -> 39.195313 | AB20: 18 | AC20: {=INDEX($A$3:$A$27,MATCH(LARGE($Z$3:$Z$27,18),$Z$3:$Z$27,0))} -> Phat | AD20: {=INDEX($B$3:$B$27,MATCH(LARGE($Z$3:$Z$27,18),$Z$3:$Z$27,0))} -> Media CTV | AE20: {=INDEX($V$3:$V$27,MATCH(LARGE($Z$3:$Z$27,18),$Z$3:$Z$27,0))} -> 39.453125 | AF20: =IF(AE20>=(W_SL+W_DOKHO+W_CL+W_BONUS),"✅ Đạt KPI",IF(AE20>=PCT_WARN,"⚠️ Gần đạt KPI","❌ Chưa đạt")) -> ❌ Chưa đạt
A21: Meran | B21: Media CTV | C21: =COUNTIF('Data thô T6'!$B:$B,A21) -> 80 | D21: =SUMIF('Data thô T6'!$B:$B,A21,'Data thô T6'!$C:$C) -> 80 | E21: =COUNTIFS('Data thô T6'!$B:$B,A21,'Data thô T6'!$E:$E,"PROX5") -> 0 | F21: =COUNTIFS('Data thô T6'!$B:$B,A21,'Data thô T6'!$E:$E,"PROX4") -> 8 | G21: =COUNTIFS('Data thô T6'!$B:$B,A21,'Data thô T6'!$E:$E,"PROX3") -> 62 | H21: =COUNTIFS('Data thô T6'!$B:$B,A21,'Data thô T6'!$E:$E,"SEM") -> 0 | I21: =COUNTIFS('Data thô T6'!$B:$B,A21,'Data thô T6'!$E:$E,"SE1") -> 1 | J21: =COUNTIFS('Data thô T6'!$B:$B,A21,'Data thô T6'!$E:$E,"E0") -> 1 | K21: =SUM(E21:J21) -> 72 | L21: =IF(C21=0,0,(E21*HS_PROX5+F21*HS_PROX4+G21*HS_PROX3+H21*HS_SEM+I21*HS_SE1+J21*HS_E0+(C21-K21)*HS_DEFAULT)/C21) -> 1.1025 | M21: =MIN(D21/TASK_TARGET,1)*W_SL -> 32 | N21: =IF(C21=0,0,MAX(0,MIN(1,(L21-HS_MIN)/(HS_MAX-HS_MIN)))*W_DOKHO) -> 7.546875 | P21: =IF(O21="","",(O21/5)*W_CL) | Q21: 0 | R21: 0 | S21: 0 | U21: =MIN(S21,W_BONUS)+Q21*TRE_TASK+R21*TRE_NGAY -> 0 | V21: =M21+N21+IF(P21="",0,P21)+U21 -> 39.546875 | W21: =RANK(V21,$V$3:$V$27,0) -> 17 | X21: =IF(V21>=(W_SL+W_DOKHO+W_CL+W_BONUS),"✅ Đạt KPI",IF(V21>=PCT_WARN,"⚠️ Gần đạt KPI","❌ Chưa đạt")) -> ❌ Chưa đạt | Z21: =V21+(ROW()-3)/100000000 -> 39.546875 | AB21: 19 | AC21: {=INDEX($A$3:$A$27,MATCH(LARGE($Z$3:$Z$27,19),$Z$3:$Z$27,0))} -> Vi | AD21: {=INDEX($B$3:$B$27,MATCH(LARGE($Z$3:$Z$27,19),$Z$3:$Z$27,0))} -> Media CTV | AE21: {=INDEX($V$3:$V$27,MATCH(LARGE($Z$3:$Z$27,19),$Z$3:$Z$27,0))} -> 39.359375 | AF21: =IF(AE21>=(W_SL+W_DOKHO+W_CL+W_BONUS),"✅ Đạt KPI",IF(AE21>=PCT_WARN,"⚠️ Gần đạt KPI","❌ Chưa đạt")) -> ❌ Chưa đạt
A22: Sean | B22: Media Key | C22: =COUNTIF('Data thô T6'!$B:$B,A22) -> 32 | D22: =SUMIF('Data thô T6'!$B:$B,A22,'Data thô T6'!$C:$C) -> 32 | E22: =COUNTIFS('Data thô T6'!$B:$B,A22,'Data thô T6'!$E:$E,"PROX5") -> 1 | F22: =COUNTIFS('Data thô T6'!$B:$B,A22,'Data thô T6'!$E:$E,"PROX4") -> 6 | G22: =COUNTIFS('Data thô T6'!$B:$B,A22,'Data thô T6'!$E:$E,"PROX3") -> 18 | H22: =COUNTIFS('Data thô T6'!$B:$B,A22,'Data thô T6'!$E:$E,"SEM") -> 0 | I22: =COUNTIFS('Data thô T6'!$B:$B,A22,'Data thô T6'!$E:$E,"SE1") -> 0 | J22: =COUNTIFS('Data thô T6'!$B:$B,A22,'Data thô T6'!$E:$E,"E0") -> 3 | K22: =SUM(E22:J22) -> 28 | L22: =IF(C22=0,0,(E22*HS_PROX5+F22*HS_PROX4+G22*HS_PROX3+H22*HS_SEM+I22*HS_SE1+J22*HS_E0+(C22-K22)*HS_DEFAULT)/C22) -> 1.1 | M22: =MIN(D22/TASK_TARGET,1)*W_SL -> 12.8 | N22: =IF(C22=0,0,MAX(0,MIN(1,(L22-HS_MIN)/(HS_MAX-HS_MIN)))*W_DOKHO) -> 7.5 | P22: =IF(O22="","",(O22/5)*W_CL) | Q22: 0 | R22: 0 | S22: 0 | U22: =MIN(S22,W_BONUS)+Q22*TRE_TASK+R22*TRE_NGAY -> 0 | V22: =M22+N22+IF(P22="",0,P22)+U22 -> 20.3 | W22: =RANK(V22,$V$3:$V$27,0) -> 24 | X22: =IF(V22>=(W_SL+W_DOKHO+W_CL+W_BONUS),"✅ Đạt KPI",IF(V22>=PCT_WARN,"⚠️ Gần đạt KPI","❌ Chưa đạt")) -> ❌ Chưa đạt | Z22: =V22+(ROW()-3)/100000000 -> 20.3 | AB22: 20 | AC22: {=INDEX($A$3:$A$27,MATCH(LARGE($Z$3:$Z$27,20),$Z$3:$Z$27,0))} -> My | AD22: {=INDEX($B$3:$B$27,MATCH(LARGE($Z$3:$Z$27,20),$Z$3:$Z$27,0))} -> Media CTV | AE22: {=INDEX($V$3:$V$27,MATCH(LARGE($Z$3:$Z$27,20),$Z$3:$Z$27,0))} -> 39.344444 | AF22: =IF(AE22>=(W_SL+W_DOKHO+W_CL+W_BONUS),"✅ Đạt KPI",IF(AE22>=PCT_WARN,"⚠️ Gần đạt KPI","❌ Chưa đạt")) -> ❌ Chưa đạt
A23: Sherry | B23: Media Key | C23: =COUNTIF('Data thô T6'!$B:$B,A23) -> 31 | D23: =SUMIF('Data thô T6'!$B:$B,A23,'Data thô T6'!$C:$C) -> 189 | E23: =COUNTIFS('Data thô T6'!$B:$B,A23,'Data thô T6'!$E:$E,"PROX5") -> 1 | F23: =COUNTIFS('Data thô T6'!$B:$B,A23,'Data thô T6'!$E:$E,"PROX4") -> 17 | G23: =COUNTIFS('Data thô T6'!$B:$B,A23,'Data thô T6'!$E:$E,"PROX3") -> 12 | H23: =COUNTIFS('Data thô T6'!$B:$B,A23,'Data thô T6'!$E:$E,"SEM") -> 0 | I23: =COUNTIFS('Data thô T6'!$B:$B,A23,'Data thô T6'!$E:$E,"SE1") -> 0 | J23: =COUNTIFS('Data thô T6'!$B:$B,A23,'Data thô T6'!$E:$E,"E0") -> 0 | K23: =SUM(E23:J23) -> 30 | L23: =IF(C23=0,0,(E23*HS_PROX5+F23*HS_PROX4+G23*HS_PROX3+H23*HS_SEM+I23*HS_SE1+J23*HS_E0+(C23-K23)*HS_DEFAULT)/C23) -> 1.2193548 | M23: =MIN(D23/TASK_TARGET,1)*W_SL -> 60 | N23: =IF(C23=0,0,MAX(0,MIN(1,(L23-HS_MIN)/(HS_MAX-HS_MIN)))*W_DOKHO) -> 9.7379032 | P23: =IF(O23="","",(O23/5)*W_CL) | Q23: 0 | R23: 0 | S23: 0 | U23: =MIN(S23,W_BONUS)+Q23*TRE_TASK+R23*TRE_NGAY -> 0 | V23: =M23+N23+IF(P23="",0,P23)+U23 -> 69.737903 | W23: =RANK(V23,$V$3:$V$27,0) -> 1 | X23: =IF(V23>=(W_SL+W_DOKHO+W_CL+W_BONUS),"✅ Đạt KPI",IF(V23>=PCT_WARN,"⚠️ Gần đạt KPI","❌ Chưa đạt")) -> ❌ Chưa đạt | Z23: =V23+(ROW()-3)/100000000 -> 69.737903 | AB23: 21 | AC23: {=INDEX($A$3:$A$27,MATCH(LARGE($Z$3:$Z$27,21),$Z$3:$Z$27,0))} -> Henri | AD23: {=INDEX($B$3:$B$27,MATCH(LARGE($Z$3:$Z$27,21),$Z$3:$Z$27,0))} -> Media CTV | AE23: {=INDEX($V$3:$V$27,MATCH(LARGE($Z$3:$Z$27,21),$Z$3:$Z$27,0))} -> 39.195312 | AF23: =IF(AE23>=(W_SL+W_DOKHO+W_CL+W_BONUS),"✅ Đạt KPI",IF(AE23>=PCT_WARN,"⚠️ Gần đạt KPI","❌ Chưa đạt")) -> ❌ Chưa đạt
A24: Charlie | B24: Media Key | C24: =COUNTIF('Data thô T6'!$B:$B,A24) -> 28 | D24: =SUMIF('Data thô T6'!$B:$B,A24,'Data thô T6'!$C:$C) -> 150 | E24: =COUNTIFS('Data thô T6'!$B:$B,A24,'Data thô T6'!$E:$E,"PROX5") -> 3 | F24: =COUNTIFS('Data thô T6'!$B:$B,A24,'Data thô T6'!$E:$E,"PROX4") -> 9 | G24: =COUNTIFS('Data thô T6'!$B:$B,A24,'Data thô T6'!$E:$E,"PROX3") -> 6 | H24: =COUNTIFS('Data thô T6'!$B:$B,A24,'Data thô T6'!$E:$E,"SEM") -> 0 | I24: =COUNTIFS('Data thô T6'!$B:$B,A24,'Data thô T6'!$E:$E,"SE1") -> 0 | J24: =COUNTIFS('Data thô T6'!$B:$B,A24,'Data thô T6'!$E:$E,"E0") -> 2 | K24: =SUM(E24:J24) -> 20 | L24: =IF(C24=0,0,(E24*HS_PROX5+F24*HS_PROX4+G24*HS_PROX3+H24*HS_SEM+I24*HS_SE1+J24*HS_E0+(C24-K24)*HS_DEFAULT)/C24) -> 1.15 | M24: =MIN(D24/TASK_TARGET,1)*W_SL -> 60 | N24: =IF(C24=0,0,MAX(0,MIN(1,(L24-HS_MIN)/(HS_MAX-HS_MIN)))*W_DOKHO) -> 8.4375 | P24: =IF(O24="","",(O24/5)*W_CL) | Q24: 0 | R24: 0 | S24: 0 | U24: =MIN(S24,W_BONUS)+Q24*TRE_TASK+R24*TRE_NGAY -> 0 | V24: =M24+N24+IF(P24="",0,P24)+U24 -> 68.4375 | W24: =RANK(V24,$V$3:$V$27,0) -> 4 | X24: =IF(V24>=(W_SL+W_DOKHO+W_CL+W_BONUS),"✅ Đạt KPI",IF(V24>=PCT_WARN,"⚠️ Gần đạt KPI","❌ Chưa đạt")) -> ❌ Chưa đạt | Z24: =V24+(ROW()-3)/100000000 -> 68.4375 | AB24: 22 | AC24: {=INDEX($A$3:$A$27,MATCH(LARGE($Z$3:$Z$27,22),$Z$3:$Z$27,0))} -> Q.Anh | AD24: {=INDEX($B$3:$B$27,MATCH(LARGE($Z$3:$Z$27,22),$Z$3:$Z$27,0))} -> Media CTV | AE24: {=INDEX($V$3:$V$27,MATCH(LARGE($Z$3:$Z$27,22),$Z$3:$Z$27,0))} -> 39.078125 | AF24: =IF(AE24>=(W_SL+W_DOKHO+W_CL+W_BONUS),"✅ Đạt KPI",IF(AE24>=PCT_WARN,"⚠️ Gần đạt KPI","❌ Chưa đạt")) -> ❌ Chưa đạt
A25: Nancy | B25: Media Key | C25: =COUNTIF('Data thô T6'!$B:$B,A25) -> 27 | D25: =SUMIF('Data thô T6'!$B:$B,A25,'Data thô T6'!$C:$C) -> 155 | E25: =COUNTIFS('Data thô T6'!$B:$B,A25,'Data thô T6'!$E:$E,"PROX5") -> 3 | F25: =COUNTIFS('Data thô T6'!$B:$B,A25,'Data thô T6'!$E:$E,"PROX4") -> 11 | G25: =COUNTIFS('Data thô T6'!$B:$B,A25,'Data thô T6'!$E:$E,"PROX3") -> 4 | H25: =COUNTIFS('Data thô T6'!$B:$B,A25,'Data thô T6'!$E:$E,"SEM") -> 0 | I25: =COUNTIFS('Data thô T6'!$B:$B,A25,'Data thô T6'!$E:$E,"SE1") -> 0 | J25: =COUNTIFS('Data thô T6'!$B:$B,A25,'Data thô T6'!$E:$E,"E0") -> 0 | K25: =SUM(E25:J25) -> 18 | L25: =IF(C25=0,0,(E25*HS_PROX5+F25*HS_PROX4+G25*HS_PROX3+H25*HS_SEM+I25*HS_SE1+J25*HS_E0+(C25-K25)*HS_DEFAULT)/C25) -> 1.1925926 | M25: =MIN(D25/TASK_TARGET,1)*W_SL -> 60 | N25: =IF(C25=0,0,MAX(0,MIN(1,(L25-HS_MIN)/(HS_MAX-HS_MIN)))*W_DOKHO) -> 9.2361111 | P25: =IF(O25="","",(O25/5)*W_CL) | Q25: 0 | R25: 0 | S25: 0 | U25: =MIN(S25,W_BONUS)+Q25*TRE_TASK+R25*TRE_NGAY -> 0 | V25: =M25+N25+IF(P25="",0,P25)+U25 -> 69.236111 | W25: =RANK(V25,$V$3:$V$27,0) -> 2 | X25: =IF(V25>=(W_SL+W_DOKHO+W_CL+W_BONUS),"✅ Đạt KPI",IF(V25>=PCT_WARN,"⚠️ Gần đạt KPI","❌ Chưa đạt")) -> ❌ Chưa đạt | Z25: =V25+(ROW()-3)/100000000 -> 69.236111 | AB25: 23 | AC25: {=INDEX($A$3:$A$27,MATCH(LARGE($Z$3:$Z$27,23),$Z$3:$Z$27,0))} -> Nah | AD25: {=INDEX($B$3:$B$27,MATCH(LARGE($Z$3:$Z$27,23),$Z$3:$Z$27,0))} -> Media CTV | AE25: {=INDEX($V$3:$V$27,MATCH(LARGE($Z$3:$Z$27,23),$Z$3:$Z$27,0))} -> 38.820312 | AF25: =IF(AE25>=(W_SL+W_DOKHO+W_CL+W_BONUS),"✅ Đạt KPI",IF(AE25>=PCT_WARN,"⚠️ Gần đạt KPI","❌ Chưa đạt")) -> ❌ Chưa đạt
A26: Nathan | B26: Media Key | C26: =COUNTIF('Data thô T6'!$B:$B,A26) -> 17 | D26: =SUMIF('Data thô T6'!$B:$B,A26,'Data thô T6'!$C:$C) -> 92 | E26: =COUNTIFS('Data thô T6'!$B:$B,A26,'Data thô T6'!$E:$E,"PROX5") -> 3 | F26: =COUNTIFS('Data thô T6'!$B:$B,A26,'Data thô T6'!$E:$E,"PROX4") -> 1 | G26: =COUNTIFS('Data thô T6'!$B:$B,A26,'Data thô T6'!$E:$E,"PROX3") -> 6 | H26: =COUNTIFS('Data thô T6'!$B:$B,A26,'Data thô T6'!$E:$E,"SEM") -> 0 | I26: =COUNTIFS('Data thô T6'!$B:$B,A26,'Data thô T6'!$E:$E,"SE1") -> 0 | J26: =COUNTIFS('Data thô T6'!$B:$B,A26,'Data thô T6'!$E:$E,"E0") -> 2 | K26: =SUM(E26:J26) -> 12 | L26: =IF(C26=0,0,(E26*HS_PROX5+F26*HS_PROX4+G26*HS_PROX3+H26*HS_SEM+I26*HS_SE1+J26*HS_E0+(C26-K26)*HS_DEFAULT)/C26) -> 1.1058824 | M26: =MIN(D26/TASK_TARGET,1)*W_SL -> 36.8 | N26: =IF(C26=0,0,MAX(0,MIN(1,(L26-HS_MIN)/(HS_MAX-HS_MIN)))*W_DOKHO) -> 7.6102941 | P26: =IF(O26="","",(O26/5)*W_CL) | Q26: 0 | R26: 0 | S26: 0 | U26: =MIN(S26,W_BONUS)+Q26*TRE_TASK+R26*TRE_NGAY -> 0 | V26: =M26+N26+IF(P26="",0,P26)+U26 -> 44.410294 | W26: =RANK(V26,$V$3:$V$27,0) -> 15 | X26: =IF(V26>=(W_SL+W_DOKHO+W_CL+W_BONUS),"✅ Đạt KPI",IF(V26>=PCT_WARN,"⚠️ Gần đạt KPI","❌ Chưa đạt")) -> ❌ Chưa đạt | Z26: =V26+(ROW()-3)/100000000 -> 44.410294 | AB26: 24 | AC26: {=INDEX($A$3:$A$27,MATCH(LARGE($Z$3:$Z$27,24),$Z$3:$Z$27,0))} -> Sean | AD26: {=INDEX($B$3:$B$27,MATCH(LARGE($Z$3:$Z$27,24),$Z$3:$Z$27,0))} -> Media Key | AE26: {=INDEX($V$3:$V$27,MATCH(LARGE($Z$3:$Z$27,24),$Z$3:$Z$27,0))} -> 20.3 | AF26: =IF(AE26>=(W_SL+W_DOKHO+W_CL+W_BONUS),"✅ Đạt KPI",IF(AE26>=PCT_WARN,"⚠️ Gần đạt KPI","❌ Chưa đạt")) -> ❌ Chưa đạt
A27: Yollie | B27: Media Key | C27: =COUNTIF('Data thô T6'!$B:$B,A27) -> 0 | D27: =SUMIF('Data thô T6'!$B:$B,A27,'Data thô T6'!$C:$C) -> 0 | E27: =COUNTIFS('Data thô T6'!$B:$B,A27,'Data thô T6'!$E:$E,"PROX5") -> 0 | F27: =COUNTIFS('Data thô T6'!$B:$B,A27,'Data thô T6'!$E:$E,"PROX4") -> 0 | G27: =COUNTIFS('Data thô T6'!$B:$B,A27,'Data thô T6'!$E:$E,"PROX3") -> 0 | H27: =COUNTIFS('Data thô T6'!$B:$B,A27,'Data thô T6'!$E:$E,"SEM") -> 0 | I27: =COUNTIFS('Data thô T6'!$B:$B,A27,'Data thô T6'!$E:$E,"SE1") -> 0 | J27: =COUNTIFS('Data thô T6'!$B:$B,A27,'Data thô T6'!$E:$E,"E0") -> 0 | K27: =SUM(E27:J27) -> 0 | L27: =IF(C27=0,0,(E27*HS_PROX5+F27*HS_PROX4+G27*HS_PROX3+H27*HS_SEM+I27*HS_SE1+J27*HS_E0+(C27-K27)*HS_DEFAULT)/C27) -> 0 | M27: =MIN(D27/TASK_TARGET,1)*W_SL -> 0 | N27: =IF(C27=0,0,MAX(0,MIN(1,(L27-HS_MIN)/(HS_MAX-HS_MIN)))*W_DOKHO) -> 0 | P27: =IF(O27="","",(O27/5)*W_CL) | Q27: 0 | R27: 0 | S27: 0 | U27: =MIN(S27,W_BONUS)+Q27*TRE_TASK+R27*TRE_NGAY -> 0 | V27: =M27+N27+IF(P27="",0,P27)+U27 -> 0 | W27: =RANK(V27,$V$3:$V$27,0) -> 25 | X27: =IF(V27>=(W_SL+W_DOKHO+W_CL+W_BONUS),"✅ Đạt KPI",IF(V27>=PCT_WARN,"⚠️ Gần đạt KPI","❌ Chưa đạt")) -> ❌ Chưa đạt | Z27: =V27+(ROW()-3)/100000000 -> 2.4e-07 | AB27: 25 | AC27: {=INDEX($A$3:$A$27,MATCH(LARGE($Z$3:$Z$27,25),$Z$3:$Z$27,0))} -> Yollie | AD27: {=INDEX($B$3:$B$27,MATCH(LARGE($Z$3:$Z$27,25),$Z$3:$Z$27,0))} -> Media Key | AE27: {=INDEX($V$3:$V$27,MATCH(LARGE($Z$3:$Z$27,25),$Z$3:$Z$27,0))} -> 0 | AF27: =IF(AE27>=(W_SL+W_DOKHO+W_CL+W_BONUS),"✅ Đạt KPI",IF(AE27>=PCT_WARN,"⚠️ Gần đạt KPI","❌ Chưa đạt")) -> ❌ Chưa đạt
A28: TỔNG (số lượng) / TRUNG BÌNH (điểm) | C28: =SUM(C3:C27) -> 3129 | D28: =SUM(D3:D27) -> 4595 | K28: =SUM(K3:K27) -> 2868 | M28: =AVERAGE(M3:M27) -> 45.84 | N28: =AVERAGE(N3:N27) -> 7.483808 | U28: =AVERAGE(U3:U27) -> 0 | V28: =AVERAGE(V3:V27) -> 53.323808
A30: ⚠ Task gán cho AM / Intern / tên không xác định (số lượng nhỏ) — KHÔNG tính vào KPI
A31: Tên trong dữ liệu | B31: Loại | C31: Số task
A32: Sonny Nguyen (Intern) | B32: Intern | C32: 21
A33: Kimmy Le | B33: Chưa xác định | C33: 20
A34: Anna | B34: AM (gán nhầm/kiêm nhiệm?) | C34: 2
A35: Elio Nguyen (Intern) | B35: Intern | C35: 2
A36: Vo Hoang kiet | B36: Chưa xác định | C36: 1
A37: Fury Nguyen | B37: Chưa xác định | C37: 1
A39: Nguồn DUY NHẤT: file "check - Export data - Task Design 6-2026.csv". File không có cột status/deadline nên KHÔNG lọc theo hoàn thành và KHÔNG tự tính trễ hạn (cột Số task trễ hạn / Tổng ngày trễ chuyển lại thành nhập tay). Bỏ qua 28 task không có ai được giao. Phat, Henri, Meran giờ có đủ 80 task/người.

Sheet Template tháng mới
A1: TEMPLATE TÍNH ĐIỂM KPI DESIGNER — THÁNG __ /____ (nhân bản sheet này mỗi tháng) | AB1: 🏆 BẢNG XẾP HẠNG (tự động, giảm dần theo Tổng điểm KPI)
A2: Designer | B2: Nhóm | C2: Tổng số task | D2: Tổng điểm thô (loại task) | E2: PROX5 | F2: PROX4 | G2: PROX3 | H2: SEM | I2: SE1 | J2: E0 | K2: Đã phân loại gói | L2: Hệ số độ khó TB | M2: Điểm số lượng | N2: Điểm độ khó | O2: Chất lượng TB (1-5) | P2: Điểm chất lượng | Q2: Số task trễ hạn | R2: Tổng ngày trễ | S2: Điểm bonus | T2: Ghi chú bonus | U2: Điểm bonus/trễ | V2: TỔNG ĐIỂM KPI (%) | W2: Xếp hạng | X2: Trạng thái | Z2: Khoá (ẩn) | AB2: Hạng | AC2: Designer | AD2: Nhóm | AE2: Tổng điểm (%) | AF2: Trạng thái
A3: Heidi | B3: Media Key | C3: =COUNTIF('Data thô (dán hàng tháng)'!$B:$B,A3) -> 0 | D3: =SUMIF('Data thô (dán hàng tháng)'!$B:$B,A3,'Data thô (dán hàng tháng)'!$C:$C) -> 0 | E3: 0 | F3: 0 | G3: 0 | H3: 0 | I3: 0 | J3: 0 | K3: =SUM(E3:J3) -> 0 | L3: =IF(C3=0,0,(E3*HS_PROX5+F3*HS_PROX4+G3*HS_PROX3+H3*HS_SEM+I3*HS_SE1+J3*HS_E0+(C3-K3)*HS_DEFAULT)/C3) -> 0 | M3: =MIN(D3/TASK_TARGET,1)*W_SL -> 0 | N3: =IF(C3=0,0,MAX(0,MIN(1,(L3-HS_MIN)/(HS_MAX-HS_MIN)))*W_DOKHO) -> 0 | P3: =IF(O3="","",(O3/5)*W_CL) | Q3: 0 | R3: 0 | S3: 0 | U3: =MIN(S3,W_BONUS)+Q3*TRE_TASK+R3*TRE_NGAY -> 0 | V3: =M3+N3+IF(P3="",0,P3)+U3 -> 0 | W3: =RANK(V3,$V$3:$V$25,0) -> 1 | X3: =IF(V3>=(W_SL+W_DOKHO+W_CL+W_BONUS),"✅ Đạt KPI",IF(V3>=PCT_WARN,"⚠️ Gần đạt KPI","❌ Chưa đạt")) -> ❌ Chưa đạt | Z3: =V3+(ROW()-3)/100000000 -> 0 | AB3: 1 | AC3: {=INDEX($A$3:$A$25,MATCH(LARGE($Z$3:$Z$25,1),$Z$3:$Z$25,0))} -> Meran | AD3: {=INDEX($B$3:$B$25,MATCH(LARGE($Z$3:$Z$25,1),$Z$3:$Z$25,0))} -> Media CTV | AE3: {=INDEX($V$3:$V$25,MATCH(LARGE($Z$3:$Z$25,1),$Z$3:$Z$25,0))} -> 0 | AF3: =IF(AE3>=(W_SL+W_DOKHO+W_CL+W_BONUS),"✅ Đạt KPI",IF(AE3>=PCT_WARN,"⚠️ Gần đạt KPI","❌ Chưa đạt")) -> ❌ Chưa đạt
A4: Titus | B4: Media Key | C4: =COUNTIF('Data thô (dán hàng tháng)'!$B:$B,A4) -> 0 | D4: =SUMIF('Data thô (dán hàng tháng)'!$B:$B,A4,'Data thô (dán hàng tháng)'!$C:$C) -> 0 | E4: 0 | F4: 0 | G4: 0 | H4: 0 | I4: 0 | J4: 0 | K4: =SUM(E4:J4) -> 0 | L4: =IF(C4=0,0,(E4*HS_PROX5+F4*HS_PROX4+G4*HS_PROX3+H4*HS_SEM+I4*HS_SE1+J4*HS_E0+(C4-K4)*HS_DEFAULT)/C4) -> 0 | M4: =MIN(D4/TASK_TARGET,1)*W_SL -> 0 | N4: =IF(C4=0,0,MAX(0,MIN(1,(L4-HS_MIN)/(HS_MAX-HS_MIN)))*W_DOKHO) -> 0 | P4: =IF(O4="","",(O4/5)*W_CL) | Q4: 0 | R4: 0 | S4: 0 | U4: =MIN(S4,W_BONUS)+Q4*TRE_TASK+R4*TRE_NGAY -> 0 | V4: =M4+N4+IF(P4="",0,P4)+U4 -> 0 | W4: =RANK(V4,$V$3:$V$25,0) -> 1 | X4: =IF(V4>=(W_SL+W_DOKHO+W_CL+W_BONUS),"✅ Đạt KPI",IF(V4>=PCT_WARN,"⚠️ Gần đạt KPI","❌ Chưa đạt")) -> ❌ Chưa đạt | Z4: =V4+(ROW()-3)/100000000 -> 1e-08 | AB4: 2 | AC4: {=INDEX($A$3:$A$25,MATCH(LARGE($Z$3:$Z$25,2),$Z$3:$Z$25,0))} -> Henri | AD4: {=INDEX($B$3:$B$25,MATCH(LARGE($Z$3:$Z$25,2),$Z$3:$Z$25,0))} -> Media CTV | AE4: {=INDEX($V$3:$V$25,MATCH(LARGE($Z$3:$Z$25,2),$Z$3:$Z$25,0))} -> 0 | AF4: =IF(AE4>=(W_SL+W_DOKHO+W_CL+W_BONUS),"✅ Đạt KPI",IF(AE4>=PCT_WARN,"⚠️ Gần đạt KPI","❌ Chưa đạt")) -> ❌ Chưa đạt
A5: Ocean | B5: Media Key | C5: =COUNTIF('Data thô (dán hàng tháng)'!$B:$B,A5) -> 0 | D5: =SUMIF('Data thô (dán hàng tháng)'!$B:$B,A5,'Data thô (dán hàng tháng)'!$C:$C) -> 0 | E5: 0 | F5: 0 | G5: 0 | H5: 0 | I5: 0 | J5: 0 | K5: =SUM(E5:J5) -> 0 | L5: =IF(C5=0,0,(E5*HS_PROX5+F5*HS_PROX4+G5*HS_PROX3+H5*HS_SEM+I5*HS_SE1+J5*HS_E0+(C5-K5)*HS_DEFAULT)/C5) -> 0 | M5: =MIN(D5/TASK_TARGET,1)*W_SL -> 0 | N5: =IF(C5=0,0,MAX(0,MIN(1,(L5-HS_MIN)/(HS_MAX-HS_MIN)))*W_DOKHO) -> 0 | P5: =IF(O5="","",(O5/5)*W_CL) | Q5: 0 | R5: 0 | S5: 0 | U5: =MIN(S5,W_BONUS)+Q5*TRE_TASK+R5*TRE_NGAY -> 0 | V5: =M5+N5+IF(P5="",0,P5)+U5 -> 0 | W5: =RANK(V5,$V$3:$V$25,0) -> 1 | X5: =IF(V5>=(W_SL+W_DOKHO+W_CL+W_BONUS),"✅ Đạt KPI",IF(V5>=PCT_WARN,"⚠️ Gần đạt KPI","❌ Chưa đạt")) -> ❌ Chưa đạt | Z5: =V5+(ROW()-3)/100000000 -> 2e-08 | AB5: 3 | AC5: {=INDEX($A$3:$A$25,MATCH(LARGE($Z$3:$Z$25,3),$Z$3:$Z$25,0))} -> Phat | AD5: {=INDEX($B$3:$B$25,MATCH(LARGE($Z$3:$Z$25,3),$Z$3:$Z$25,0))} -> Media CTV | AE5: {=INDEX($V$3:$V$25,MATCH(LARGE($Z$3:$Z$25,3),$Z$3:$Z$25,0))} -> 0 | AF5: =IF(AE5>=(W_SL+W_DOKHO+W_CL+W_BONUS),"✅ Đạt KPI",IF(AE5>=PCT_WARN,"⚠️ Gần đạt KPI","❌ Chưa đạt")) -> ❌ Chưa đạt
A6: Julie | B6: Media Key | C6: =COUNTIF('Data thô (dán hàng tháng)'!$B:$B,A6) -> 0 | D6: =SUMIF('Data thô (dán hàng tháng)'!$B:$B,A6,'Data thô (dán hàng tháng)'!$C:$C) -> 0 | E6: 0 | F6: 0 | G6: 0 | H6: 0 | I6: 0 | J6: 0 | K6: =SUM(E6:J6) -> 0 | L6: =IF(C6=0,0,(E6*HS_PROX5+F6*HS_PROX4+G6*HS_PROX3+H6*HS_SEM+I6*HS_SE1+J6*HS_E0+(C6-K6)*HS_DEFAULT)/C6) -> 0 | M6: =MIN(D6/TASK_TARGET,1)*W_SL -> 0 | N6: =IF(C6=0,0,MAX(0,MIN(1,(L6-HS_MIN)/(HS_MAX-HS_MIN)))*W_DOKHO) -> 0 | P6: =IF(O6="","",(O6/5)*W_CL) | Q6: 0 | R6: 0 | S6: 0 | U6: =MIN(S6,W_BONUS)+Q6*TRE_TASK+R6*TRE_NGAY -> 0 | V6: =M6+N6+IF(P6="",0,P6)+U6 -> 0 | W6: =RANK(V6,$V$3:$V$25,0) -> 1 | X6: =IF(V6>=(W_SL+W_DOKHO+W_CL+W_BONUS),"✅ Đạt KPI",IF(V6>=PCT_WARN,"⚠️ Gần đạt KPI","❌ Chưa đạt")) -> ❌ Chưa đạt | Z6: =V6+(ROW()-3)/100000000 -> 3e-08 | AB6: 4 | AC6: {=INDEX($A$3:$A$25,MATCH(LARGE($Z$3:$Z$25,4),$Z$3:$Z$25,0))} -> Q.Anh | AD6: {=INDEX($B$3:$B$25,MATCH(LARGE($Z$3:$Z$25,4),$Z$3:$Z$25,0))} -> Media CTV | AE6: {=INDEX($V$3:$V$25,MATCH(LARGE($Z$3:$Z$25,4),$Z$3:$Z$25,0))} -> 0 | AF6: =IF(AE6>=(W_SL+W_DOKHO+W_CL+W_BONUS),"✅ Đạt KPI",IF(AE6>=PCT_WARN,"⚠️ Gần đạt KPI","❌ Chưa đạt")) -> ❌ Chưa đạt
A7: Helia | B7: Media Key | C7: =COUNTIF('Data thô (dán hàng tháng)'!$B:$B,A7) -> 0 | D7: =SUMIF('Data thô (dán hàng tháng)'!$B:$B,A7,'Data thô (dán hàng tháng)'!$C:$C) -> 0 | E7: 0 | F7: 0 | G7: 0 | H7: 0 | I7: 0 | J7: 0 | K7: =SUM(E7:J7) -> 0 | L7: =IF(C7=0,0,(E7*HS_PROX5+F7*HS_PROX4+G7*HS_PROX3+H7*HS_SEM+I7*HS_SE1+J7*HS_E0+(C7-K7)*HS_DEFAULT)/C7) -> 0 | M7: =MIN(D7/TASK_TARGET,1)*W_SL -> 0 | N7: =IF(C7=0,0,MAX(0,MIN(1,(L7-HS_MIN)/(HS_MAX-HS_MIN)))*W_DOKHO) -> 0 | P7: =IF(O7="","",(O7/5)*W_CL) | Q7: 0 | R7: 0 | S7: 0 | U7: =MIN(S7,W_BONUS)+Q7*TRE_TASK+R7*TRE_NGAY -> 0 | V7: =M7+N7+IF(P7="",0,P7)+U7 -> 0 | W7: =RANK(V7,$V$3:$V$25,0) -> 1 | X7: =IF(V7>=(W_SL+W_DOKHO+W_CL+W_BONUS),"✅ Đạt KPI",IF(V7>=PCT_WARN,"⚠️ Gần đạt KPI","❌ Chưa đạt")) -> ❌ Chưa đạt | Z7: =V7+(ROW()-3)/100000000 -> 4e-08 | AB7: 5 | AC7: {=INDEX($A$3:$A$25,MATCH(LARGE($Z$3:$Z$25,5),$Z$3:$Z$25,0))} -> Uri | AD7: {=INDEX($B$3:$B$25,MATCH(LARGE($Z$3:$Z$25,5),$Z$3:$Z$25,0))} -> Media CTV | AE7: {=INDEX($V$3:$V$25,MATCH(LARGE($Z$3:$Z$25,5),$Z$3:$Z$25,0))} -> 0 | AF7: =IF(AE7>=(W_SL+W_DOKHO+W_CL+W_BONUS),"✅ Đạt KPI",IF(AE7>=PCT_WARN,"⚠️ Gần đạt KPI","❌ Chưa đạt")) -> ❌ Chưa đạt
A8: Clara | B8: Media Key | C8: =COUNTIF('Data thô (dán hàng tháng)'!$B:$B,A8) -> 0 | D8: =SUMIF('Data thô (dán hàng tháng)'!$B:$B,A8,'Data thô (dán hàng tháng)'!$C:$C) -> 0 | E8: 0 | F8: 0 | G8: 0 | H8: 0 | I8: 0 | J8: 0 | K8: =SUM(E8:J8) -> 0 | L8: =IF(C8=0,0,(E8*HS_PROX5+F8*HS_PROX4+G8*HS_PROX3+H8*HS_SEM+I8*HS_SE1+J8*HS_E0+(C8-K8)*HS_DEFAULT)/C8) -> 0 | M8: =MIN(D8/TASK_TARGET,1)*W_SL -> 0 | N8: =IF(C8=0,0,MAX(0,MIN(1,(L8-HS_MIN)/(HS_MAX-HS_MIN)))*W_DOKHO) -> 0 | P8: =IF(O8="","",(O8/5)*W_CL) | Q8: 0 | R8: 0 | S8: 0 | U8: =MIN(S8,W_BONUS)+Q8*TRE_TASK+R8*TRE_NGAY -> 0 | V8: =M8+N8+IF(P8="",0,P8)+U8 -> 0 | W8: =RANK(V8,$V$3:$V$25,0) -> 1 | X8: =IF(V8>=(W_SL+W_DOKHO+W_CL+W_BONUS),"✅ Đạt KPI",IF(V8>=PCT_WARN,"⚠️ Gần đạt KPI","❌ Chưa đạt")) -> ❌ Chưa đạt | Z8: =V8+(ROW()-3)/100000000 -> 5e-08 | AB8: 6 | AC8: {=INDEX($A$3:$A$25,MATCH(LARGE($Z$3:$Z$25,6),$Z$3:$Z$25,0))} -> Nah | AD8: {=INDEX($B$3:$B$25,MATCH(LARGE($Z$3:$Z$25,6),$Z$3:$Z$25,0))} -> Media CTV | AE8: {=INDEX($V$3:$V$25,MATCH(LARGE($Z$3:$Z$25,6),$Z$3:$Z$25,0))} -> 0 | AF8: =IF(AE8>=(W_SL+W_DOKHO+W_CL+W_BONUS),"✅ Đạt KPI",IF(AE8>=PCT_WARN,"⚠️ Gần đạt KPI","❌ Chưa đạt")) -> ❌ Chưa đạt
A9: Mio | B9: Media Key | C9: =COUNTIF('Data thô (dán hàng tháng)'!$B:$B,A9) -> 0 | D9: =SUMIF('Data thô (dán hàng tháng)'!$B:$B,A9,'Data thô (dán hàng tháng)'!$C:$C) -> 0 | E9: 0 | F9: 0 | G9: 0 | H9: 0 | I9: 0 | J9: 0 | K9: =SUM(E9:J9) -> 0 | L9: =IF(C9=0,0,(E9*HS_PROX5+F9*HS_PROX4+G9*HS_PROX3+H9*HS_SEM+I9*HS_SE1+J9*HS_E0+(C9-K9)*HS_DEFAULT)/C9) -> 0 | M9: =MIN(D9/TASK_TARGET,1)*W_SL -> 0 | N9: =IF(C9=0,0,MAX(0,MIN(1,(L9-HS_MIN)/(HS_MAX-HS_MIN)))*W_DOKHO) -> 0 | P9: =IF(O9="","",(O9/5)*W_CL) | Q9: 0 | R9: 0 | S9: 0 | U9: =MIN(S9,W_BONUS)+Q9*TRE_TASK+R9*TRE_NGAY -> 0 | V9: =M9+N9+IF(P9="",0,P9)+U9 -> 0 | W9: =RANK(V9,$V$3:$V$25,0) -> 1 | X9: =IF(V9>=(W_SL+W_DOKHO+W_CL+W_BONUS),"✅ Đạt KPI",IF(V9>=PCT_WARN,"⚠️ Gần đạt KPI","❌ Chưa đạt")) -> ❌ Chưa đạt | Z9: =V9+(ROW()-3)/100000000 -> 6e-08 | AB9: 7 | AC9: {=INDEX($A$3:$A$25,MATCH(LARGE($Z$3:$Z$25,7),$Z$3:$Z$25,0))} -> Vi | AD9: {=INDEX($B$3:$B$25,MATCH(LARGE($Z$3:$Z$25,7),$Z$3:$Z$25,0))} -> Media CTV | AE9: {=INDEX($V$3:$V$25,MATCH(LARGE($Z$3:$Z$25,7),$Z$3:$Z$25,0))} -> 0 | AF9: =IF(AE9>=(W_SL+W_DOKHO+W_CL+W_BONUS),"✅ Đạt KPI",IF(AE9>=PCT_WARN,"⚠️ Gần đạt KPI","❌ Chưa đạt")) -> ❌ Chưa đạt
A10: Daniel | B10: Media Key | C10: =COUNTIF('Data thô (dán hàng tháng)'!$B:$B,A10) -> 0 | D10: =SUMIF('Data thô (dán hàng tháng)'!$B:$B,A10,'Data thô (dán hàng tháng)'!$C:$C) -> 0 | E10: 0 | F10: 0 | G10: 0 | H10: 0 | I10: 0 | J10: 0 | K10: =SUM(E10:J10) -> 0 | L10: =IF(C10=0,0,(E10*HS_PROX5+F10*HS_PROX4+G10*HS_PROX3+H10*HS_SEM+I10*HS_SE1+J10*HS_E0+(C10-K10)*HS_DEFAULT)/C10) -> 0 | M10: =MIN(D10/TASK_TARGET,1)*W_SL -> 0 | N10: =IF(C10=0,0,MAX(0,MIN(1,(L10-HS_MIN)/(HS_MAX-HS_MIN)))*W_DOKHO) -> 0 | P10: =IF(O10="","",(O10/5)*W_CL) | Q10: 0 | R10: 0 | S10: 0 | U10: =MIN(S10,W_BONUS)+Q10*TRE_TASK+R10*TRE_NGAY -> 0 | V10: =M10+N10+IF(P10="",0,P10)+U10 -> 0 | W10: =RANK(V10,$V$3:$V$25,0) -> 1 | X10: =IF(V10>=(W_SL+W_DOKHO+W_CL+W_BONUS),"✅ Đạt KPI",IF(V10>=PCT_WARN,"⚠️ Gần đạt KPI","❌ Chưa đạt")) -> ❌ Chưa đạt | Z10: =V10+(ROW()-3)/100000000 -> 7e-08 | AB10: 8 | AC10: {=INDEX($A$3:$A$25,MATCH(LARGE($Z$3:$Z$25,8),$Z$3:$Z$25,0))} -> My | AD10: {=INDEX($B$3:$B$25,MATCH(LARGE($Z$3:$Z$25,8),$Z$3:$Z$25,0))} -> Media CTV | AE10: {=INDEX($V$3:$V$25,MATCH(LARGE($Z$3:$Z$25,8),$Z$3:$Z$25,0))} -> 0 | AF10: =IF(AE10>=(W_SL+W_DOKHO+W_CL+W_BONUS),"✅ Đạt KPI",IF(AE10>=PCT_WARN,"⚠️ Gần đạt KPI","❌ Chưa đạt")) -> ❌ Chưa đạt
A11: Barry | B11: Media Key | C11: =COUNTIF('Data thô (dán hàng tháng)'!$B:$B,A11) -> 0 | D11: =SUMIF('Data thô (dán hàng tháng)'!$B:$B,A11,'Data thô (dán hàng tháng)'!$C:$C) -> 0 | E11: 0 | F11: 0 | G11: 0 | H11: 0 | I11: 0 | J11: 0 | K11: =SUM(E11:J11) -> 0 | L11: =IF(C11=0,0,(E11*HS_PROX5+F11*HS_PROX4+G11*HS_PROX3+H11*HS_SEM+I11*HS_SE1+J11*HS_E0+(C11-K11)*HS_DEFAULT)/C11) -> 0 | M11: =MIN(D11/TASK_TARGET,1)*W_SL -> 0 | N11: =IF(C11=0,0,MAX(0,MIN(1,(L11-HS_MIN)/(HS_MAX-HS_MIN)))*W_DOKHO) -> 0 | P11: =IF(O11="","",(O11/5)*W_CL) | Q11: 0 | R11: 0 | S11: 0 | U11: =MIN(S11,W_BONUS)+Q11*TRE_TASK+R11*TRE_NGAY -> 0 | V11: =M11+N11+IF(P11="",0,P11)+U11 -> 0 | W11: =RANK(V11,$V$3:$V$25,0) -> 1 | X11: =IF(V11>=(W_SL+W_DOKHO+W_CL+W_BONUS),"✅ Đạt KPI",IF(V11>=PCT_WARN,"⚠️ Gần đạt KPI","❌ Chưa đạt")) -> ❌ Chưa đạt | Z11: =V11+(ROW()-3)/100000000 -> 8e-08 | AB11: 9 | AC11: {=INDEX($A$3:$A$25,MATCH(LARGE($Z$3:$Z$25,9),$Z$3:$Z$25,0))} -> Sean | AD11: {=INDEX($B$3:$B$25,MATCH(LARGE($Z$3:$Z$25,9),$Z$3:$Z$25,0))} -> Media Key | AE11: {=INDEX($V$3:$V$25,MATCH(LARGE($Z$3:$Z$25,9),$Z$3:$Z$25,0))} -> 0 | AF11: =IF(AE11>=(W_SL+W_DOKHO+W_CL+W_BONUS),"✅ Đạt KPI",IF(AE11>=PCT_WARN,"⚠️ Gần đạt KPI","❌ Chưa đạt")) -> ❌ Chưa đạt
A12: Sherry | B12: Media Key | C12: =COUNTIF('Data thô (dán hàng tháng)'!$B:$B,A12) -> 0 | D12: =SUMIF('Data thô (dán hàng tháng)'!$B:$B,A12,'Data thô (dán hàng tháng)'!$C:$C) -> 0 | E12: 0 | F12: 0 | G12: 0 | H12: 0 | I12: 0 | J12: 0 | K12: =SUM(E12:J12) -> 0 | L12: =IF(C12=0,0,(E12*HS_PROX5+F12*HS_PROX4+G12*HS_PROX3+H12*HS_SEM+I12*HS_SE1+J12*HS_E0+(C12-K12)*HS_DEFAULT)/C12) -> 0 | M12: =MIN(D12/TASK_TARGET,1)*W_SL -> 0 | N12: =IF(C12=0,0,MAX(0,MIN(1,(L12-HS_MIN)/(HS_MAX-HS_MIN)))*W_DOKHO) -> 0 | P12: =IF(O12="","",(O12/5)*W_CL) | Q12: 0 | R12: 0 | S12: 0 | U12: =MIN(S12,W_BONUS)+Q12*TRE_TASK+R12*TRE_NGAY -> 0 | V12: =M12+N12+IF(P12="",0,P12)+U12 -> 0 | W12: =RANK(V12,$V$3:$V$25,0) -> 1 | X12: =IF(V12>=(W_SL+W_DOKHO+W_CL+W_BONUS),"✅ Đạt KPI",IF(V12>=PCT_WARN,"⚠️ Gần đạt KPI","❌ Chưa đạt")) -> ❌ Chưa đạt | Z12: =V12+(ROW()-3)/100000000 -> 9e-08 | AB12: 10 | AC12: {=INDEX($A$3:$A$25,MATCH(LARGE($Z$3:$Z$25,10),$Z$3:$Z$25,0))} -> Yollie | AD12: {=INDEX($B$3:$B$25,MATCH(LARGE($Z$3:$Z$25,10),$Z$3:$Z$25,0))} -> Media Key | AE12: {=INDEX($V$3:$V$25,MATCH(LARGE($Z$3:$Z$25,10),$Z$3:$Z$25,0))} -> 0 | AF12: =IF(AE12>=(W_SL+W_DOKHO+W_CL+W_BONUS),"✅ Đạt KPI",IF(AE12>=PCT_WARN,"⚠️ Gần đạt KPI","❌ Chưa đạt")) -> ❌ Chưa đạt
A13: Nathan | B13: Media Key | C13: =COUNTIF('Data thô (dán hàng tháng)'!$B:$B,A13) -> 0 | D13: =SUMIF('Data thô (dán hàng tháng)'!$B:$B,A13,'Data thô (dán hàng tháng)'!$C:$C) -> 0 | E13: 0 | F13: 0 | G13: 0 | H13: 0 | I13: 0 | J13: 0 | K13: =SUM(E13:J13) -> 0 | L13: =IF(C13=0,0,(E13*HS_PROX5+F13*HS_PROX4+G13*HS_PROX3+H13*HS_SEM+I13*HS_SE1+J13*HS_E0+(C13-K13)*HS_DEFAULT)/C13) -> 0 | M13: =MIN(D13/TASK_TARGET,1)*W_SL -> 0 | N13: =IF(C13=0,0,MAX(0,MIN(1,(L13-HS_MIN)/(HS_MAX-HS_MIN)))*W_DOKHO) -> 0 | P13: =IF(O13="","",(O13/5)*W_CL) | Q13: 0 | R13: 0 | S13: 0 | U13: =MIN(S13,W_BONUS)+Q13*TRE_TASK+R13*TRE_NGAY -> 0 | V13: =M13+N13+IF(P13="",0,P13)+U13 -> 0 | W13: =RANK(V13,$V$3:$V$25,0) -> 1 | X13: =IF(V13>=(W_SL+W_DOKHO+W_CL+W_BONUS),"✅ Đạt KPI",IF(V13>=PCT_WARN,"⚠️ Gần đạt KPI","❌ Chưa đạt")) -> ❌ Chưa đạt | Z13: =V13+(ROW()-3)/100000000 -> 1e-07 | AB13: 11 | AC13: {=INDEX($A$3:$A$25,MATCH(LARGE($Z$3:$Z$25,11),$Z$3:$Z$25,0))} -> Alex | AD13: {=INDEX($B$3:$B$25,MATCH(LARGE($Z$3:$Z$25,11),$Z$3:$Z$25,0))} -> Media Key | AE13: {=INDEX($V$3:$V$25,MATCH(LARGE($Z$3:$Z$25,11),$Z$3:$Z$25,0))} -> 0 | AF13: =IF(AE13>=(W_SL+W_DOKHO+W_CL+W_BONUS),"✅ Đạt KPI",IF(AE13>=PCT_WARN,"⚠️ Gần đạt KPI","❌ Chưa đạt")) -> ❌ Chưa đạt
